Workbook

Sheet Κατάσταση Κεφαλαίων
A1: ΕΥΡΕΤΗΡΙΟ
A2: ΒΙΒΛΙΟΥ ΥΛΙΚΟΥ Δ/ΣΗΣ Π.Υ. ΝΟΜΟΥ ΚΕΡΚΥΡΑΣ ΟΙΚΟΝΟΜΙΚΟΥ ΕΤΟΥΣ 2024
A3: Α/Α | B3: ΚΕΦΑΛΑΙΟ ΜΕΡΟΣ ΤΜΗΜΑ | C3: ΣΕΛΙΔΑ | D3: ΟΝΟΜΑΣΙΑ ΥΛΙΚΟΥ
A4: 1 | B4: A.Α.Α. | C4: 2,3,4,5 | D4: ΥΓΕΙΟΝΟΜΙΚΟ ΥΛΙΚΟ | F4: Υγειονομικό Υλικό
A5: 2 | B5: Β.Α.Α. | C5: 6,7 | D5: ΕΙΔΗ ΜΑΓΕΙΡΙΚΩΝ ΣΚΕΥΩΝ | F5: Μαγειρικά Σκεύη
A6: 3 | B6: Β.Α.Β. | C6: 8,9 | D6: ΕΙΔΗ ΕΣΤΙΑΣΕΩΣ | F6: Είδη Εστιάσεως
A7: 4 | B7: Β.Α.Γ. | C7: 10,11,12,13,14,15 | D7: ΕΙΔΗ ΙΜΑΤΙΣΜΟΥ | F7: Είδη Ιματισμού
A8: 5 | B8: Β.Α.Δ. | C8: 16,17 | D8: ΣΗΜΑΙΕΣ - ΣΗΜΑΤΑ | F8: Σημαίες-Εμβλήματα
A9: 6 | B9: Β.Α.Ε. | C9: 18,19,20,21 | D9: ΑΝΑΠΝΕΥΣΤΙΚΕΣ ΣΥΣΚΕΥΕΣ - ΠΑΡΕΛΚΟΜΕΝΑ | F9: Αναπνευστικές
A10: 7 | B10: Γ.Α.Α. | C10: 22,23,24,25,26,27 | D10: ΟΧΗΜΑΤΑ ΕΝ ΓΕΝΕΙ | F10: Οχήματα
A11: 8 | B11: Γ.Α.Γ. | C11: 28,29 | D11: ΑΝΤΑΛΛΑΚΤΙΚΑ ΟΧΗΜΑΤΩΝ MAGIRUS DEUTZ | F11: Ανταλλακτικά Οχ.
A12: 9 | B12: Γ.Α.Ζ. | C12: 30,31 | D12: ΑΝΤΑΛΛΑΚΤΙΚΑ ΥΔΡΑΥΛΙΚΩΝ ΚΛΙΜΑΚΩΝ | F12: Παρελκ.Κλίμακ.Οχ
A13: 10 | B13: Γ.Α.Η. | C13: 32,33,34,35,36,37,38,39,184,185,186,187,188,189,190,191 | D13: ΑΝΤΑΛΛΑΚΤΙΚΑ ΔΙΑΦΟΡΩΝ ΤΥΠΩΝ ΟΧΗΜΑΤΩΝ | F13: Παρελκόμενα Οχ.
A14: 11 | B14: Γ.Α.Θ. | C14: 40,41 | D14: ΕΡΓΑΛΕΙΑ ΟΧΗΜΑΤΩΝ ΕΝ ΓΕΝΕΙ | F14: Εργαλεία Οχ.
A15: 12 | B15: Γ.Α.Ι. | C15: 42,43,44,45,46,47,48,49 | D15: ΔΙΑΦΟΡΕΣ ΥΛΕΣ ΑΝΑΛΩΣΙΜΑ | F15: Καύσιμα
... A36: 34 | B36: Δ.Β.Ε. | C36: 180,181 | D36: ΕΙΔΙΚΟΣ ΠΥΡ/ΚΟΣ ΕΞΟΠΛΙΣΜΟΣ | F36: ΚΕΝΗ
A37: 35 | B37: Δ.Β.Ζ. | C37: 182,183 | D37: ΕΝΑΕΡΙΑ ΜΕΣΑ-ΠΑΡΕΛΚΟΜΕΝΑ
A38: 36
A39: Βεβαιώνεται ότι το παρών Βιβλίο Υλικού της αυθύπαρκτης Διαχείρισης Υλικού της ΔI.Π.Υ.Νομού Κέρκυρας σελιδομετρήθηκε και περιέχει Εκατόν Ογδόντα πέντε(185) σελίδες,υπό αύξοντα αριθμό ένα (1) έως και Εκατόν Ογδόντα πέντε(185)
A42: Το Οικονομικό Συμβούλιο
B44: Ο Πρόεδρος | D44: Ο Διαχειριστής Υλικού
B48: Νικόλαος Γ. Κόλλας | D48: Μπόγδος Κ. Νεκτάριος
B49: Πύραρχος ΓΚ | D49: Υποπυραγός ΕΤ ΓΚ

Sheet Σελίδα 1
A1: ΥΛΙΚΟΥ ΔΙΟΙΚΗΣΗΣ Π.Υ. ΝΟΜΟΥ ΚΕΡΚΥΡΑΣ
E3: 2025
A12: Χ | B12: Π | C12: Χ | D12: Π | E12: Χ | F12: Π | G12: Χ | H12: Π | I12: Χ | J12: Π | K12: Χ | L12: Π | M12: Χ | N12: Π | O12: Χ | P12: Π | Q12: Χ | R12: Π | S12: Χ | T12: Π

Sheet AΑΑ(2)
A1: ΒΙΒΛΙΟ | X1: ΥΛΙΚΟΥ ΔΙΟΙΚΗΣΗΣ Π.Υ. ΝΟΜΟΥ ΚΕΡΚΥΡΑΣ
A3: Αύξων αριθμός δικαιολογητικών | B3: 2026 | D3: Σελίδα 2 | K3: Κιβώτια Φαρμακείων Α΄ Βοηθειών | M3: Στηθοσκόπιο Ιατρείου | O3: Φορεία Μεταφοράς τραυματιών (πτυσόμενα) | Q3: Νάρθηκες Γενικά κνήμης-χειρός | S3: Συσκευή Τεχνιτής αναπνοής | U3: Συσκευές Ανάληψης με φιαλίδιο & αεροπνεύμονα | X3: Συσκευή Καρδιο-αναλήψης | Z3: Σάκοι πτωμάτων | AB3: Κολλάρα Αυχένα | AD3: Συσκευές Αναπνευστικής Αναννήψεως | AF3: Κουβέρτα Ισοθερμική | AH3: Φορεία Α/Δ (αναδιπλούμενα) | AJ3: Φορεία τύπου Κουταλιού | AL3: Φορεία τύπου καλαθιού (IVECO Δασών) | AN3: Νάρθηκας (σύστημα) ακινητοποίησης κεφαλής φορείου | AP3: Φορεία τύπου σανίδας
D5: ΛΕΠΤΟΜΕΡΕΙΕΣ
B7: Μήνας | C7: Ημέρα
D8: Αύξων αριθμός ονομαστικού | K8: 31 | M8: 51 | O8: 59 | Q8: 79 | S8: 80 | U8: 110 | X8: 117 | Z8: 217 | AB8: 265 | AD8: 274 | AF8: 281α | AH8: 284 | AJ8: 284α | AL8: 284β | AN8: 293 | AP8: 298
D10: Α.΄Α.΄Α.΄
D12: ΥΓΕΙΟΝΟΜΙΚΟ ΥΛΙΚΟ | K12: Χ | L12: Π | M12: Χ | N12: Π | O12: Χ | P12: Π | Q12: Χ | R12: Π | S12: Χ | T12: Π | U12: Χ | V12: Π | X12: Χ | Y12: Π | Z12: Χ | AA12: Π | AB12: Χ | AC12: Π | AD12: Χ | AE12: Π | AF12: Χ | AG12: Π | AH12: Χ | AI12: Π | AJ12: Χ | AK12: Π | AL12: Χ | AM12: Π | AN12: Χ | AO12: Π | AP12: Χ | AQ12: Π
B13: Ιανουάριος | C13: 1 | D13: Υπόλοιπο από μεταφορά έτους 2023 | K13: 43 | L13: 0 | M13: 1 | N13: 0 | O13: 4 | P13: 0 | Q13: 10 | R13: 0 | S13: 1 | T13: 0 | U13: 4 | V13: 0 | X13: 1 | Y13: 0 | Z13: 20 | AA13: 0 | AB13: 5 | AC13: 0 | AD13: 1 | AE13: 0 | AF13: 2 | AG13: 0 | AH13: 8 | AI13: 0 | AJ13: 3 | AK13: 0 | AL13: 5 | AM13: 0 | AN13: 2 | AO13: 0 | AP13: 7 | AQ13: 0
A14: 1 | B14: Μάιος | C14: 15 | D14: Εγγραφή με τ.α.α.119 ΥΔΙΠΥΛ για Π.Σ. 5428 (Δγη 2208 Φ.544.1/15-01-2026) | K14: 1
A15: 2 | B15: Μάιος | C15: 20 | D15: Εγγραφή με τ.α.α. 983 ΥΔΙΠΥΛ για Π.Σ.5740 και Π.Σ.5741 (Δγη11526/26-06-2026) | K15: 2
A16: 3 | B16: Μάιος | C16: 22 | D16: Εγγραφή με τ.α.α.1650 ΥΔΙΠΥΛ για Π.Σ.5479 (Δγη 12424 Φ.544.1/02-03-2026) | K16: 1 | Z16: 3

Sheet AΑΑ(4)
A1: ΒΙΒΛΙΟ | X1: ΥΛΙΚΟΥ ΔΙΟΙΚΗΣΗΣ Π.Υ. ΝΟΜΟΥ ΚΕΡΚΥΡΑΣ
A3: Αύξων αριθμός δικαιολογητικών | B3: 2026 | D3: Σελίδα 4
D5: ΛΕΠΤΟΜΕΡΕΙΕΣ
B7: Μήνας | C7: Ημέρα
D8: Αύξων αριθμός ονομαστικού
D10: Α.΄Α.΄Α.΄
D12: ΥΓΕΙΟΝΟΜΙΚΟ ΥΛΙΚΟ | K12: Χ | L12: Π | M12: Χ | N12: Π | O12: Χ | P12: Π | Q12: Χ | R12: Π | S12: Χ | T12: Π | U12: Χ | V12: Π | X12: Χ | Y12: Π | Z12: Χ | AA12: Π | AB12: Χ | AC12: Π | AD12: Χ | AE12: Π | AF12: Χ | AG12: Π | AH12: Χ | AI12: Π | AJ12: Χ | AK12: Π | AL12: Χ | AM12: Π | AN12: Χ | AO12: Π | AP12: Χ | AQ12: Π
D13: Υπόλοιπο από μεταφορά έτους 2023

Sheet ΒΑΑ(6)
A1: ΒΙΒΛΙΟ | X1: ΥΛΙΚΟΥ ΔΙΟΙΚΗΣΗΣ Π.Υ. ΝΟΜΟΥ ΚΕΡΚΥΡΑΣ
A3: Αύξων αριθμός δικαιολογητικών | B3: 2026 | D3: Σελίδα 6 | K3: Ντουλάπες μεταλλίκες διάφορες | M3: Ηλεκτρικές <Συσκευές> κουζίινες (4) εστιών με ηλεκτρικό φούρνο | O3: Συσκευές υγραερίου τριών(3) εστιών με ηλεκτρικό κλίβανο | Q3: Τοστιέρες γενικά | S3: Καφετιέρα παραγωγής καφέ φίλτρου | U3: Φουρνάκι Ηλεκτρικό Davoline Futura (Αξιωματικών) | X3: Φούρνος Μικροκυμάτων
D5: ΛΕΠΤΟΜΕΡΕΙΕΣ
B7: Μήνας | C7: Ημέρα
D8: Αύξων αριθμός ονομαστικού | K8: 4α | M8: 46 | O8: 49 | Q8: 83 | S8: 91 | U8: 96 | X8: 98
D10: Β.΄Α.΄Α.΄
D12: ΕΙΔΗ ΜΑΓΕΙΡΙΚΩΝ ΣΚΕΥΩΝ | K12: Χ | L12: Π | M12: Χ | N12: Π | O12: Χ | P12: Π | Q12: Χ | R12: Π | S12: Χ | T12: Π | U12: Χ | V12: Π | X12: Χ | Y12: Π | Z12: Χ | AA12: Π | AB12: Χ | AC12: Π | AD12: Χ | AE12: Π | AF12: Χ | AG12: Π | AH12: Χ | AI12: Π | AJ12: Χ | AK12: Π | AL12: Χ | AM12: Π | AN12: Χ | AO12: Π | AP12: Χ | AQ12: Π
B13: Ιανουάριος | C13: 1 | D13: Υπόλοιπο από μεταφορά έτους 2023 | K13: 1 | L13: 0 | M13: 2 | N13: 0 | O13: 1 | P13: 0 | Q13: 1 | R13: 0 | S13: 1 | T13: 0 | U13: 1 | V13: 0 | X13: 1 | Y13: 0

Sheet ΒΑΒ(8)
A1: ΒΙΒΛΙΟ | X1: ΥΛΙΚΟΥ ΔΙΟΙΚΗΣΗΣ Π.Υ. ΝΟΜΟΥ ΚΕΡΚΥΡΑΣ
A3: Αύξων αριθμός δικαιολογητικών | B3: 2026 | D3: Σελίδα 8 | K3: Ψυγείο φορητό πάγου τροφίμων | M3: Ψυγεία ηλεκτρικά οικιακής χρήσεως | O3: Ψυγεία ηλεκτρικά επαγγελματικής χρήσεως | Q3: Κουζίνες Ηλεκτρικές διαφόρων τύπων
D5: ΛΕΠΤΟΜΕΡΕΙΕΣ
B7: Μήνας | C7: Ημέρα
D8: Αύξων αριθμός ονομαστικού | K8: 39α | M8: 40 | O8: 41 | Q8: 91
D10: Β.΄Α.΄Β.΄
D12: ΕΙΔΗ ΕΣΤΙΑΣΕΩΣ | K12: Χ | L12: Π | M12: Χ | N12: Π | O12: Χ | P12: Π | Q12: Χ | R12: Π | S12: Χ | T12: Π | U12: Χ | V12: Π | X12: Χ | Y12: Π | Z12: Χ | AA12: Π | AB12: Χ | AC12: Π | AD12: Χ | AE12: Π | AF12: Χ | AG12: Π | AH12: Χ | AI12: Π | AJ12: Χ | AK12: Π | AL12: Χ | AM12: Π | AN12: Χ | AO12: Π | AP12: Χ | AQ12: Π
B13: Ιανουάριος | C13: 1 | D13: Υπόλοιπο από μεταφορά έτους 2023 | K13: 1 | L13: 0 | M13: 13 | N13: 0 | O13: 1 | P13: 0 | Q13: 5 | R13: 0

Sheet ΒΑΓ(10)
A1: ΒΙΒΛΙΟ | X1: ΥΛΙΚΟΥ ΔΙΟΙΚΗΣΗΣ Π.Υ. ΝΟΜΟΥ ΚΕΡΚΥΡΑΣ
A3: Αύξων αριθμός δικαιολογητικών | B3: 2026 | D3: Σελίδα 10 | K3: Ειδικές Ζώνες "5" σημείων πρόσδεσης & Πυρ/κές ζώνες διάσωσης | M3: Ειδικές Ζώνες Διάσωσης | O3: Κλίνες Σιδηρές | Q3: Κρεβάτια κοινά Ξύλινα | S3: Κουβέρτες Μάλλινες τραυματιών | U3: Συσκευές για ενδοσυνεννόηση Πυρ/κών κρανών | X3: Στρώματα | Z3: Στρώματα τύπου στωματέξ (με καλύμματα) | AB3: Υποδήματα ελαστικά μηρού (γαλότσες) σε ζεύγη | AD3: Υποδήματα ελαστικά υψηλά (μπότες πλημμυρών) σε ζεύγη | AF3: Πλαστικά Παγούρια "5" λίτρων | AH3: Σετ Φόρμες αδιάβροχες (Νιντσεράδες) χιτώνιο/ παντελ. | AJ3: Γιλέκα αντανακλαστικά | AL3: Κράνη Μοτοσυκ/στών | AN3: Ζευγάρια Γάντια | AP3: Ορειβατικά Κράνη
D5: ΛΕΠΤΟΜΕΡΕΙΕΣ
B7: Μήνας | C7: Ημέρα
D8: Αύξων αριθμός ονομαστικού | K8: 4 | M8: 4α | O8: 7 | Q8: 9 | S8: 10 | U8: 13δ | X8: 21 | Z8: 26α | AB8: 93 | AD8: 94 | AF8: 149 | AH8: 160 | AJ8: 165 | AL8: 166 | AN8: 169α | AP8: 175
D10: Β.΄Α.΄Γ.΄
D12: ΕΙΔΗ ΙΜΑΤΙΣΜΟΥ | K12: Χ | L12: Π | M12: Χ | N12: Π | O12: Χ | P12: Π | Q12: Χ | R12: Π | S12: Χ | T12: Π | U12: Χ | V12: Π | X12: Χ | Y12: Π | Z12: Χ | AA12: Π | AB12: Χ | AC12: Π | AD12: Χ | AE12: Π | AF12: Χ | AG12: Π | AH12: Χ | AI12: Π | AJ12: Χ | AK12: Π | AL12: Χ | AM12: Π | AN12: Χ | AO12: Π | AP12: Χ | AQ12: Π
B13: Ιανουάριος | C13: 1 | D13: Υπόλοιπο από μεταφορά έτους 2023 | K13: 14 | L13: 0 | M13: 2 | N13: 0 | O13: 68 | P13: 0 | Q13: 27 | R13: 0 | S13: 4 | T13: 0 | U13: 2 | V13: 0 | X13: 10 | Y13: 0 | Z13: 70 | AA13: 0 | AB13: 89 | AC13: 0 | AD13: 10 | AE13: 0 | AF13: 2 | AG13: 0 | AH13: 28 | AI13: 0 | AJ13: 2 | AK13: 0 | AL13: 6 | AM13: 0 | AN13: 255 | AO13: 0 | AP13: 6 | AQ13: 0
A14: 1 | B14: Μάιος | C14: 14 | D14: Εγγραφή με τ.α.α.13 για αγορά ειδών από το εμπόριο(Απ.Ανάλ.Υποχρ.3279/9-3-2026) | AN14: 3
A15: 2 | B15: Μάιος | C15: 22 | D15: Εγγραφή με τ.α.α.1652 ΥΔΙΠΥΛ για Π.Σ.5479 (Δγη 12424 Φ.544.1/02-03-2026)

Sheet ΒΑΓ(12)
A1: ΒΙΒΛΙΟ | X1: ΥΛΙΚΟΥ ΔΙΟΙΚΗΣΗΣ Π.Υ. ΝΟΜΟΥ ΚΕΡΚΥΡΑΣ
A3: Αύξων αριθμός δικαιολογητικών | B3: 2026 | D3: Σελίδα 12 | K3: Ζακέτες αδιάβροχες τύπου Ανοραλ | M3: Αδιάβροχα | O3: Φακοί ορειβατικών κρανών | Q3: Ελαστικά Υποδήματα σε ζεύγη (μέσης) με ενσωματωμένο αδιάβροχο παντελόνι | S3: Ζεύγη γάντια μοτοσυκ/τών | U3: Τζάκετ μοτοσυκ/τών | X3: Επιγονατίδες μοτοσυκ/τών | Z3: Θώρακες μοτοσυκ/των | AB3: Άρβυλα (Αστικά) | AD3: Άρβυλα Δασοπυροσβεστών | AF3: Κουκούλες Διαφυγής | AH3: Φόρμες Υλοτομίας | AJ3: Σάκοι μεταφοράς εργαλείων | AL3: Σκηνές 8 ατόμων | AN3: Φόρμες Εργασίας Εποχικών
D5: ΛΕΠΤΟΜΕΡΕΙΕΣ
B7: Μήνας | C7: Ημέρα
D8: Αύξων αριθμός ονομαστικού | K8: 179 | M8: 179δ | O8: 182 | Q8: 187 | S8: 229 | U8: 230 | X8: 232 | Z8: 233 | AB8: 152 | AD8: 152α | AF8: 234α | AH8: 96α | AJ8: 150β | AL8: 133 | AN8: 196
D10: Β.΄Α.΄Γ.΄
D12: ΕΙΔΗ ΙΜΑΤΙΣΜΟΥ | K12: Χ | L12: Π | M12: Χ | N12: Π | O12: Χ | P12: Π | Q12: Χ | R12: Π | S12: Χ | T12: Π | U12: Χ | V12: Π | X12: Χ | Y12: Π | Z12: Χ | AA12: Π | AB12: Χ | AC12: Π | AD12: Χ | AE12: Π | AF12: Χ | AG12: Π | AH12: Χ | AI12: Π | AJ12: Χ | AK12: Π | AL12: Χ | AM12: Π | AN12: Χ | AO12: Π | AP12: Χ | AQ12: Π
B13: Ιανουάριος | C13: 1 | D13: Υπόλοιπο από μεταφορά έτους 2023 | K13: 25 | L13: 0 | M13: 42 | N13: 0 | O13: 11 | P13: 0 | Q13: 10 | R13: 0 | S13: 6 | T13: 0 | U13: 6 | V13: 0 | X13: 2 | Y13: 0 | Z13: 2 | AA13: 0 | AB13: 140 | AC13: 0 | AD13: 178 | AE13: 0 | AF13: 2 | AG13: 0 | AH13: 10 | AI13: 0 | AJ13: 54 | AK13: 0 | AL13: 0 | AM13: 0 | AN13: 0 | AO13: 0
A14: 1 | AJ14: 36

Sheet ΒΑΓ(14)
A1: ΒΙΒΛΙΟ | X1: ΥΛΙΚΟΥ ΔΙΟΙΚΗΣΗΣ Π.Υ. ΝΟΜΟΥ ΚΕΡΚΥΡΑΣ
A3: Αύξων αριθμός δικαιολογητικών | B3: 2026 | D3: Σελίδα 14
D5: ΛΕΠΤΟΜΕΡΕΙΕΣ
B7: Μήνας | C7: Ημέρα
D8: Αύξων αριθμός ονομαστικού
D10: Β.΄Α.΄Γ.΄
D12: ΕΙΔΗ ΙΜΑΤΙΣΜΟΥ | K12: Χ | L12: Π | M12: Χ | N12: Π | O12: Χ | P12: Π | Q12: Χ | R12: Π | S12: Χ | T12: Π | U12: Χ | V12: Π | X12: Χ | Y12: Π | Z12: Χ | AA12: Π | AB12: Χ | AC12: Π | AD12: Χ | AE12: Π | AF12: Χ | AG12: Π | AH12: Χ | AI12: Π | AJ12: Χ | AK12: Π | AL12: Χ | AM12: Π | AN12: Χ | AO12: Π | AP12: Χ | AQ12: Π
D13: Υπόλοιπο από μεταφορά έτους 2023

Sheet ΒΑΔ(16)
A1: ΒΙΒΛΙΟ | X1: ΥΛΙΚΟΥ ΔΙΟΙΚΗΣΗΣ Π.Υ. ΝΟΜΟΥ ΚΕΡΚΥΡΑΣ
A3: Αύξων αριθμός δικαιολογητικών | B3: 2026 | D3: Σελίδα 16 | K3: Εμβλήματα αναμνηστικά Π.Σ. | M3: Εμβλήματα ορειχάλκινα μεγάλα | O3: Εμβλήματα ορειχάλκινα μικρά | Q3: Σημαίες Δημοσίων Καταστημάτων
D5: ΛΕΠΤΟΜΕΡΕΙΕΣ
B7: Μήνας | C7: Ημέρα
D8: Αύξων αριθμός ονομαστικού | K8: 3 | M8: 4 | O8: 5 | Q8: 14
D10: Β.΄Α.΄Δ.΄
D12: ΣΗΜΑΙΕΣ - ΣΗΜΑΤΑ | K12: Χ | L12: Π | M12: Χ | N12: Π | O12: Χ | P12: Π | Q12: Χ | R12: Π | S12: Χ | T12: Π | U12: Χ | V12: Π | X12: Χ | Y12: Π | Z12: Χ | AA12: Π | AB12: Χ | AC12: Π | AD12: Χ | AE12: Π | AF12: Χ | AG12: Π | AH12: Χ | AI12: Π | AJ12: Χ | AK12: Π | AL12: Χ | AM12: Π | AN12: Χ | AO12: Π | AP12: Χ | AQ12: Π
B13: Ιανουάριος | C13: 1 | D13: Υπόλοιπο από μεταφορά έτους 2023 | K13: 1 | L13: 0 | M13: 1 | N13: 0 | O13: 1 | P13: 0 | Q13: 0 | R13: 0

Sheet ΒΑΕ(18)
A1: ΒΙΒΛΙΟ | X1: ΥΛΙΚΟΥ ΔΙΟΙΚΗΣΗΣ Π.Υ. ΝΟΜΟΥ ΚΕΡΚΥΡΑΣ
A3: Αύξων αριθμός δικαιολογητικών | B3: 2026 | D3: Σελίδα 18 | K3: Αναπν. Συσκευές μικρού μεγέθους περιορισμένου χώρου πλήρεις | M3: Αναπνευστικές Συσκευές Α/Κ με φιάλες ανθρα/νημάτων 6,8 Lt (Πλήρεις) | O3: Αεροσυμπιεστές πληρώσεως φιαλών Α/Σ (Bauer) | Q3: Προσωπίδες διαφόρων τύπων από ελαστικό | S3: Φιάλες χαλύβδυνες (6Lt) αναπνευστικών συσκευών | U3: Φίλτρα ατομικών προσωπίδων | X3: Συσκευή ανίχνευσης εκρηκτικών μειγμάτων Mini-Warn B Νο: 6408080 | Z3: Ατομικές προσωπίδες αναπνευστικών συσκευών | AB3: Εφεδρικά συστήματα παροχής αέρα | AD3: Πλάτες από πλαστικό αναπνευστικών συσκευών (Interspiro) | AF3: Αεροπνεύμονες αναπνευστικών συσκευών | AH3: Βιβλίο οδηγιών χρήσης ανιχνευτή αερίων | AJ3: Επαναφ/ζόμενη μπαταρία ανιχνευτή αερίων | AL3: Σύνδεσμος Φόρτισης ανιχνευτή αερίων | AN3: Φορτιστής μπαταρίας ανιχνευτή αερίων | AP3: Θήκη μεταφοράς ανιχνευτή αερίων
D5: ΛΕΠΤΟΜΕΡΕΙΕΣ
B7: Μήνας | C7: Ημέρα
D8: Αύξων αριθμός ονομαστικού | K8: 4β | M8: 4γ | O8: 6 | Q8: 19 | S8: 26α | U8: 28 | X8: 42β | Z8: 43 | AB8: 93 | AD8: 123 | AF8: 145 | AH8: 153α | AJ8: 179 | AL8: 180 | AN8: 181 | AP8: 182
D10: Β.΄Α.΄Ε.΄
D12: ΑΝΑΠΝΕΥΣΤΙΚΕΣ ΣΥΣΚΕΥΕΣ - ΠΑΡΕΛΚΟΜΕΝΑ | K12: Χ | L12: Π | M12: Χ | N12: Π | O12: Χ | P12: Π | Q12: Χ | R12: Π | S12: Χ | T12: Π | U12: Χ | V12: Π | X12: Χ | Y12: Π | Z12: Χ | AA12: Π | AB12: Χ | AC12: Π | AD12: Χ | AE12: Π | AF12: Χ | AG12: Π | AH12: Χ | AI12: Π | AJ12: Χ | AK12: Π | AL12: Χ | AM12: Π | AN12: Χ | AO12: Π | AP12: Χ | AQ12: Π
B13: Ιανουάριος | C13: 1 | D13: Υπόλοιπο από μεταφορά έτους 2023 | K13: 2 | L13: 0 | M13: 6 | N13: 0 | O13: 1 | P13: 0 | Q13: 27 | R13: 0 | S13: 73 | T13: 0 | U13: 77 | V13: 0 | X13: 2 | Y13: 0 | Z13: 88 | AA13: 0 | AB13: 2 | AC13: 0 | AD13: 53 | AE13: 0 | AF13: 74 | AG13: 0 | AH13: 1 | AI13: 0 | AJ13: 1 | AK13: 0 | AL13: 1 | AM13: 0 | AN13: 1 | AO13: 0 | AP13: 1 | AQ13: 0
A14: 1 | B14: Απρίλιος | C14: 8 | D14: Εγγραφή με τ.α.α.15/2026 για επισκευή ΑΣΑΚ (Αποφ.Αναλ.Υποχ.2245/19-02-2026)
A15: 2 | B15: Απρίλιος | C15: 21 | D15: Εγγραφή με τ.α.α.11/2026 για επισκευή ΑΣΑΚ (Απευθ.Ανάθ.1165 Φ.511/13-03-2026))
A16: 3 | B16: Μάιος | C16: 13 | D16: Εγγραφή με τ.α.α.12 για αγορά ειδών από το εμπόριο(Απ.Αναλ.Υποχρ.3356/10-3-2026)
A17: 4 | B17: Μάιος | C17: 22 | D17: Εγγραφή με τ.α.α.1651 ΥΔΙΠΥΛ για Π.Σ.5479 (Δγη 12424 Φ.544.1/02-03-2026) | M17: 3
A18: 5 | B18: Ιούλιος | C18: 29 | D18: Εγγραφή με τ.α.α.33 για αγορά ειδών από το εμπόριο(Απ.Αναλ.Υποχρ.13811/22-7-2026)
A19: 6 | B19: Ιούλιος | C19: 30 | D19: Εγγραφή με τ.α.α.36 για αγορά ειδών από το εμπόριο(Απ.Αναλ.Υποχρ.13811/22-7-2026)

Sheet ΒΑΕ(20)
A1: ΒΙΒΛΙΟ | X1: ΥΛΙΚΟΥ ΔΙΟΙΚΗΣΗΣ Π.Υ. ΝΟΜΟΥ ΚΕΡΚΥΡΑΣ
A3: Αύξων αριθμός δικαιολογητικών | B3: 2026 | D3: Σελίδα 20 | K3: Χειροκίνητη αντλία ανιχνευτή αερίων | M3: Πληρωτής με σωλήνα 10μ. Ανιχνευτή αερίων | O3: Τηλεσκοπικός ιστός ανιχνευτή αερίων | Q3: Φιάλες Ανθρακονη/των (6,8 lt) | S3: Συσκευή Συναγερμού Ακινητοποιημένου Ατόμου | U3: Φακοί | X3: Φορτιστές Μπαταριών | Z3: Σετ Αντ/κών για έλεγχο εξαετίας | AB3: Αντ/κα Επισκευής Γενικά | AD3: Σωλήνες Μανόμετρων | AF3: Μανόμετρα
D5: ΛΕΠΤΟΜΕΡΕΙΕΣ
B7: Μήνας | C7: Ημέρα
D8: Αύξων αριθμός ονομαστικού | K8: 183 | M8: 184 | O8: 185 | Q8: 203 | S8: 218 | U8: 51 | X8: 80 | Z8: 109 | AB8: 221 | AD8: 24 | AF8: 17
D10: Β.΄Α.΄Ε.΄
D12: ΑΝΑΠΝΕΥΣΤΙΚΕΣ ΣΥΣΚΕΥΕΣ - ΠΑΡΕΛΚΟΜΕΝΑ | K12: Χ | L12: Π | M12: Χ | N12: Π | O12: Χ | P12: Π | Q12: Χ | R12: Π | S12: Χ | T12: Π | U12: Χ | V12: Π | X12: Χ | Y12: Π | Z12: Χ | AA12: Π | AB12: Χ | AC12: Π | AD12: Χ | AE12: Π | AF12: Χ | AG12: Π | AH12: Χ | AI12: Π | AJ12: Χ | AK12: Π | AL12: Χ | AM12: Π | AN12: Χ | AO12: Π | AP12: Χ | AQ12: Π
B13: Ιανουάριος | C13: 1 | D13: Υπόλοιπο από μεταφορά έτους 2023 | K13: 1 | L13: 0 | M13: 1 | N13: 0 | O13: 1 | P13: 0 | Q13: 10 | R13: 0 | S13: 3 | T13: 0 | U13: 0 | V13: 0 | X13: 0 | Y13: 0 | Z13: 0 | AA13: 0 | AB13: 0 | AC13: 0 | AD13: 0 | AE13: 0 | AF13: 0 | AG13: 0
A14: 1 | Z14: 1 | AB14: 1 | AD14: 1 | AF14: 1
A15: 2 | AB15: 27 | AD15: 4 | AF15: 1
A16: 3 | AB16: 1
A17: 4
A18: 5 | AB18: 6
A19: 6 | AB19: 6

Sheet ΓΑΑ(22)
A1: ΒΙΒΛΙΟ | X1: ΥΛΙΚΟΥ ΔΙΟΙΚΗΣΗΣ Π.Υ. ΝΟΜΟΥ ΚΕΡΚΥΡΑΣ
A3: Αύξων αριθμός δικαιολογητικών | B3: 2026 | D3: Σελίδα 22 | K3: Φορτηγό κλειστό Mercedes MB-100 D | M3: Υδροφόρο 5 τόνων STEYR | O3: Επιβατικά Citroen | Q3: Επιβατικό βοηθητικό οχημα VW PASSAT (ΠΣ 4354) | S3: Πυροσβεστικά Οχήματα Αστικού Τύπου έως 1500LT | U3: Επιβατηκά οχηματα τυπου Mitstubishi (Τζιπ) | X3: Επιβατηκά οχηματα τυπου Mitstubishi L 300 (Φορτηγό Window-Van) | Z3: Επιβατηγό Opel-Vectra | AB3: Υδροφόρο 1 τόνου Mercedes 711 D | AD3: Κλιμακοφόρο όχημα 30μ SCANIA | AF3: Υδροφόρο 2,5 τόνων Mercedes Unimog 1750L(4x4) | AH3: Υδροφόρο 1 τόνου Mercedes Unimog 416/115(4x4) | AJ3: Υδροφόρο 2,5 τόνων Mercedes Unimog 2150L(4x4)2000 | AL3: Ερπυστριοφόρο BV 206 | AN3: Πλατφόρμα Πυρόσβεσης Ερπυστριοφόρο BV 206 | AP3: Πλατφόρμα Διάσωσης Ερπυστριοφόρο BV 206
D5: ΛΕΠΤΟΜΕΡΕΙΕΣ
B7: Μήνας | C7: Ημέρα
D8: Αύξων αριθμός ονομαστικού | K8: 61 | M8: 74α | O8: 362 | Q8: 102β | S8: 359 | U8: 120 | X8: 120α | Z8: 127 | AB8: 132 | AD8: 134 | AF8: 135β | AH8: 135γ | AJ8: 135ε | AL8: 148 | AN8: 149 | AP8: 150
D10: Γ.΄Α.΄Α.΄
D12: ΟΧΗΜΑΤΑ ΕΝ ΓΕΝΕΙ | K12: Χ | L12: Π | M12: Χ | N12: Π | Q12: Χ | R12: Π | S12: Χ | T12: Π | U12: Χ | V12: Π | X12: Χ | Y12: Π | Z12: Χ | AA12: Π | AB12: Χ | AC12: Π | AD12: Χ | AE12: Π | AF12: Χ | AG12: Π | AH12: Χ | AI12: Π | AJ12: Χ | AK12: Π | AL12: Χ | AM12: Π | AN12: Χ | AO12: Π | AP12: Χ | AQ12: Π
B13: Ιανουάριος | C13: 1 | D13: Υπόλοιπο από μεταφορά έτους 2023 | K13: 1 | L13: 0 | M13: 1 | N13: 0 | O13: 0 | P13: 0 | Q13: 1 | R13: 0 | S13: 0 | T13: 0 | U13: 1 | V13: 0 | X13: 1 | Y13: 0 | Z13: 1 | AA13: 0 | AB13: 1 | AC13: 0 | AD13: 1 | AE13: 0 | AF13: 1 | AG13: 0 | AH13: 3 | AI13: 0 | AJ13: 1 | AK13: 0 | AL13: 1 | AM13: 0 | AN13: 1 | AO13: 0 | AP13: 1 | AQ13: 0
A14: 1 | B14: Μάιος | C14: 15 | D14: Εγγραφή με τ.α.α.118 ΥΔΙΠΥΛ για Π.Σ. 5428 (Δγη 2208 Φ.544.1/15-01-2026))
A15: 2 | B15: Μάιος | C15: 5 | D15: Διαγραφή Π.Σ.1116 λόγω απόσυρσης(Δγη 26351 Φ.544.1 05-05-2026) | AA15: 1
A16: 3 | B16: Μάιος | C16: 20 | D16: Εγγραφή με τ.α.α. 982 ΥΔΙΠΥΛ για Π.Σ.5740 και Π.Σ.5741 (Δγη11526/26-06-2026) | O16: 2
A17: 4 | B17: Μάιος | C17: 22 | D17: Εγγραφή με τ.α.α.1649 ΥΔΙΠΥΛ για Π.Σ.5479 (Δγη 12424 Φ.544.1/02-03-2026) | S17: 1

Sheet ΓΑΑ(24)
A1: ΒΙΒΛΙΟ | X1: ΥΛΙΚΟΥ ΔΙΟΙΚΗΣΗΣ Π.Υ. ΝΟΜΟΥ ΚΕΡΚΥΡΑΣ
A3: Αύξων αριθμός δικαιολογητικών | B3: 2026 | D3: Σελίδα 24 | K3: Υδροφόρο 2,5 τόνων Iveco Magirus | M3: Οχήματα Steyr 10 τόνων (ΠΣ 1690) | O3: Επιβατηγό-Jeep Nissan TerranoSII | Q3: Επιβατηγό-Jeep CHEROKEE 2.8 (4x4) | S3: Oχημα NISSAN Pic Up (4x4) με αντλητικό συγκρότημα BMW | U3: Δίκυκλη Μοτοσικλέτα KLE 125 Kawasaki | X3: Διασωστικό Υδροφόρο Iveco | Z3: Λεωφορείο CITROEN JUMPER 15 Θέσεων | AB3: Φορτηγό Γενικής Χρήσης 1 1/4 (Καναδέζα) | AD3: Βραχιονοφόρο Καλαθοφόρο MERCEDES GB 22/3300 | AF3: Επιβατηγό SKODA OKTAVIA 1.8T | AH3: Υδροφόρο 10.000 Lt MERCEDES ACTROS | AJ3: MITSUBISHI L200 4X4 500LT | AL3: Υδροφόρο 1.000 Lt MERCEDES VARIO 315D | AN3: Υδροφόρο 2.500 Lt MERCEDES Atego(4X4) | AP3: Υδροφόρο 5.000 Lt MERCEDES ACTROS
D5: ΛΕΠΤΟΜΕΡΕΙΕΣ
B7: Μήνας | C7: Ημέρα
D8: Αύξων αριθμός ονομαστικού | K8: 154 | M8: 169 | O8: 199 | Q8: 203 | S8: 208 | U8: 210 | X8: 219 | Z8: 222 | AB8: 223 | AD8: 225 | AF8: 227 | AH8: 238 | AJ8: 239 | AL8: 242 | AN8: 253 | AP8: 274
D10: Γ.΄Α.΄Α.΄
D12: ΟΧΗΜΑΤΑ ΕΝ ΓΕΝΕΙ | K12: Χ | L12: Π | M12: Χ | N12: Π | O12: Χ | P12: Π | Q12: Χ | R12: Π | S12: Χ | T12: Π | U12: Χ | V12: Π | X12: Χ | Y12: Π | Z12: Χ | AA12: Π | AB12: Χ | AC12: Π | AD12: Χ | AE12: Π | AF12: Χ | AG12: Π | AH12: Χ | AI12: Π | AJ12: Χ | AK12: Π | AL12: Χ | AM12: Π | AN12: Χ | AO12: Π | AP12: Χ | AQ12: Π
B13: Ιανουάριος | C13: 1 | D13: Υπόλοιπο από μεταφορά έτους 2023 | K13: 1 | L13: 0 | M13: 1 | N13: 0 | O13: 1 | P13: 0 | Q13: 2 | R13: 0 | S13: 1 | T13: 0 | U13: 3 | V13: 0 | X13: 3 | Y13: 0 | Z13: 0 | AA13: 0 | AB13: 1 | AC13: 0 | AD13: 1 | AE13: 0 | AF13: 2 | AG13: 0 | AH13: 1 | AI13: 0 | AJ13: 3 | AK13: 0 | AL13: 1 | AM13: 0 | AN13: 1 | AO13: 0 | AP13: 1 | AQ13: 0
A14: 1
A15: 2
A16: 3
A17: 4

Sheet ΓΑΑ(26)
A1: ΒΙΒΛΙΟ | X1: ΥΛΙΚΟΥ ΔΙΟΙΚΗΣΗΣ Π.Υ. ΝΟΜΟΥ ΚΕΡΚΥΡΑΣ
A3: Αύξων αριθμός δικαιολογητικών | B3: 2026 | D3: Σελίδα 26 | K3: Υδροφόρο 500 Lt Isuzu (4Χ4) (ΠΣ 4685) | M3: Υδροφόρο 2.500 Lt Iveco-Magirus (4Χ4) | O3: Οχήματα τύποου VAN Mercedes Sprider | Q3: Πυροσβεστικό Όχημα IVECO TRAKKER 10.000 l | S3: Oχημα MAZDA (4X4 Diesel) | U3: Λεωφορείο TEMSA BG 1 27+1 Θέσεων | X3: IVECO ML-150E25 4000LT | Z3: Λεωφορείο Mercedes Sprinter 313 Cdi 8+1 Θεσεων | AB3: Υδροφόρο NISSAN ATLEON 4X2 1000LT | AD3: Υδροφόρο Mercedes LF/16-1222 AF | AF3: Πυροσβεστικό όχημα 1000lt (4x4) BREMACH (ΠΣ 4330) | AH3: CITROEN C15E (Ελαφρύ Βαν) | AJ3: ΟΧΗΜΑΤΑ ΤΥΠΟΥ VAN MERCEDES VITO 4X4 (ΓΕΝΙΚΑ) | AL3: ΠΥΡΟΣΒΕΣΤΙΚΑ ΟΧΗΜΑΤΑ ISUZU | AN3: Οχήματα Επιβατικά τύπου MAZDA | AP3: Οχήματα Σεισμών 4Χ4 Mercedes Atego
D5: ΛΕΠΤΟΜΕΡΕΙΕΣ
B7: Μήνας | C7: Ημέρα
D8: Αύξων αριθμός ονομαστικού | K8: 283 | M8: 284α | O8: 285α | Q8: 288 | S8: 290 | U8: 297 | X8: 303 | Z8: 314 | AB8: 316 | AD8: 317 | AF8: 327 | AH8: 347 | AJ8: 285β | AL8: 283α | AN8: 116 | AP8: 257
D10: Γ.΄Α.΄Α.΄
D12: ΟΧΗΜΑΤΑ ΕΝ ΓΕΝΕΙ | K12: Χ | L12: Π | M12: Χ | N12: Π | O12: Χ | P12: Π | Q12: Χ | R12: Π | S12: Χ | T12: Π | U12: Χ | V12: Π | X12: Χ | Y12: Π | Z12: Χ | AA12: Π | AB12: Χ | AC12: Π | AD12: Χ | AE12: Π | AF12: Χ | AG12: Π | AH12: Χ | AI12: Π | AJ12: Χ | AK12: Π | AL12: Χ | AM12: Π | AN12: Χ | AO12: Π | AP12: Χ | AQ12: Π
B13: Ιανουάριος | C13: 1 | D13: Υπόλοιπο από μεταφορά έτους 2023 | K13: 1 | L13: 0 | M13: 3 | N13: 0 | O13: 1 | P13: 0 | Q13: 1 | R13: 0 | S13: 1 | T13: 0 | U13: 1 | V13: 0 | X13: 3 | Y13: 0 | Z13: 2 | AA13: 0 | AB13: 3 | AC13: 0 | AD13: 1 | AE13: 0 | AF13: 1 | AG13: 0 | AH13: 1 | AI13: 0 | AJ13: 1 | AK13: 0 | AL13: 1 | AM13: 0 | AN13: 1 | AO13: 0 | AP13: 1 | AQ13: 0
A14: 1 | AJ14: 1
A15: 2
A16: 3
A17: 4

Sheet ΓΑΓ(28)
A1: ΒΙΒΛΙΟ | X1: ΥΛΙΚΟΥ ΔΙΟΙΚΗΣΗΣ Π.Υ. ΝΟΜΟΥ ΚΕΡΚΥΡΑΣ
A3: Αύξων αριθμός δικαιολογητικών | B3: 2026 | D3: Σελίδα 28 | K3: Εφεδρικός τροχός | M3: Μοχλοί γρύλου | O3: Καλύμματα
D5: ΛΕΠΤΟΜΕΡΕΙΕΣ
B7: Μήνας | C7: Ημέρα
D8: Αύξων αριθμός ονομαστικού | K8: 220 | M8: 246 | O8: 123
D10: Γ.΄Α.΄Γ.΄
D12: ΑΝΤΑΛΛΑΚΤΙΚΑ ΟΧΗΜΑΤΩΝ MAGIRUS DEUTZ | K12: Χ | L12: Π | M12: Χ | N12: Π | O12: Χ | P12: Π | Q12: Χ | R12: Π | S12: Χ | T12: Π | U12: Χ | V12: Π | X12: Χ | Y12: Π | Z12: Χ | AA12: Π | AB12: Χ | AC12: Π | AD12: Χ | AE12: Π | AF12: Χ | AG12: Π | AH12: Χ | AI12: Π | AJ12: Χ | AK12: Π | AL12: Χ | AM12: Π | AN12: Χ | AO12: Π | AP12: Χ | AQ12: Π
B13: Ιανουάριος | C13: 1 | D13: Υπόλοιπο από μεταφορά έτους 2023 | K13: 1 | L13: 0 | M13: 4 | N13: 0 | O13: 0 | P13: 0

Sheet ΓΑΖ(30)
A1: ΒΙΒΛΙΟ | X1: ΥΛΙΚΟΥ ΔΙΟΙΚΗΣΗΣ Π.Υ. ΝΟΜΟΥ ΚΕΡΚΥΡΑΣ
A3: Αύξων αριθμός δικαιολογητικών | B3: 2026 | D3: Σελίδα 30 | K3: Μοχλοί Σωληνωτοί χειροκίνητης ανόρθωσης κλιμακίων | M3: Φορητό τηλεχειριστήριο κλιμακοφόρου οχήματος | O3: Μανιβέλλα Χειροκίνητη Κλιμακοφόρου SCANIA | Q3: Κλειδιά Κλιμακοφόρου SCANIA
D5: ΛΕΠΤΟΜΕΡΕΙΕΣ
B7: Μήνας | C7: Ημέρα
D8: Αύξων αριθμός ονομαστικού | K8: 244 | M8: 245 | O8: 257 | Q8: 261
D10: Γ.΄Α.΄Ζ.΄
D12: ΑΝΤΑΛΛΑΚΤΙΚΑ ΥΔΡΑΥΛΙΚΩΝ ΚΛΙΜΑΚΩΝ | K12: Χ | L12: Π | M12: Χ | N12: Π | O12: Χ | P12: Π | Q12: Χ | R12: Π | S12: Χ | T12: Π | U12: Χ | V12: Π | X12: Χ | Y12: Π | Z12: Χ | AA12: Π | AB12: Χ | AC12: Π | AD12: Χ | AE12: Π | AF12: Χ | AG12: Π | AH12: Χ | AI12: Π | AJ12: Χ | AK12: Π | AL12: Χ | AM12: Π | AN12: Χ | AO12: Π | AP12: Χ | AQ12: Π
B13: Ιανουάριος | C13: 1 | D13: Υπόλοιπο από μεταφορά έτους 2023 | K13: 1 | L13: 0 | M13: 2 | N13: 0 | O13: 1 | P13: 0 | Q13: 9 | R13: 0

Sheet ΓΑΗ(32)
A1: ΒΙΒΛΙΟ | X1: ΥΛΙΚΟΥ ΔΙΟΙΚΗΣΗΣ Π.Υ. ΝΟΜΟΥ ΚΕΡΚΥΡΑΣ
A3: Αύξων αριθμός δικαιολογητικών | B3: 2026 | D3: Σελίδα 32 | K3: Αντιολισθητικές αλυσίδες σε ζεύγη | M3: Βιβλία οδηγιών χρήσης & συντήρησης οχημάτων | O3: Τάκοι ακινητοποίησης διάφοροι | Q3: Εφεδρικοί τροχοί οχημάτων | S3: Πλαστικές δεξαμενές | U3: Πλαστικές δεξαμενές | X3: Τάπα πλεύσης για το ερπιστρυοφόρο BV-206 | Z3: Σειρά εργαλείων και ανταλακτικών αντλίας BMW του ΠΣ 2454 | AB3: Ερπύστριες | AD3: Αντλίες Ύδατος Κινητήρων | AF3: Δακτύλιοι Ελαστικοί Διάφοροι | AH3: Ιμάντες Ανεμιστήρων-Βεντιλατέρ | AJ3: Κλειδαριές Οχημάτων Γενικά | AL3: Σιαγόνες Πέδησης Οχημάτων πλήρης σε ζεύγη | AN3: Φίλτρα Ελαίου Διαφόρων Οχημάτων | AP3: Φίλτρα Αέρος Διαφόρων Οχημάτων
D5: ΛΕΠΤΟΜΕΡΕΙΕΣ
B7: Μήνας | C7: Ημέρα
D8: Αύξων αριθμός ονομαστικού | K8: 11 | M8: 35 | O8: 197 | Q8: 220 | S8: 418 | U8: 418α | X8: 431 | Z8: 452 | AB8: 465 | AD8: 18 | AF8: 50 | AH8: 109 | AJ8: 127 | AL8: 189 | AN8: 230 | AP8: 233
D10: Γ.΄Α.΄Η.΄
D12: ΑΝΤΑΛΛΑΚΤΙΚΑ ΔΙΑΦΟΡΩΝ ΤΥΠΩΝ ΟΧΗΜΑΤΩΝ | K12: Χ | L12: Π | M12: Χ | N12: Π | O12: Χ | P12: Π | Q12: Χ | R12: Π | S12: Χ | T12: Π | U12: Χ | V12: Π | X12: Χ | Y12: Π | Z12: Χ | AA12: Π | AB12: Χ | AC12: Π | AD12: Χ | AE12: Π | AF12: Χ | AG12: Π | AH12: Χ | AI12: Π | AJ12: Χ | AK12: Π | AL12: Χ | AM12: Π | AN12: Χ | AO12: Π | AP12: Χ | AQ12: Π
B13: Ιανουάριος | C13: 1 | D13: Υπόλοιπο από μεταφορά έτους 2023 | K13: 59 | L13: 0 | M13: 105 | N13: 0 | O13: 66 | P13: 0 | Q13: 18 | R13: 0 | S13: 1 | T13: 0 | U13: 4 | V13: 0 | X13: 1 | Y13: 0 | Z13: 1 | AA13: 0 | AB13: 4 | AC13: 0 | AD13: 1 | AE13: 0 | AF13: 125 | AG13: 0 | AH13: 18 | AI13: 0 | AJ13: 1 | AK13: 0 | AL13: 2 | AM13: 0 | AN13: 34 | AO13: 0 | AP13: 28 | AQ13: 0
A14: 1 | B14: Φεβρουάριος | C14: 10 | D14: Εγγραφή με τ.α.α.1/2026 για αγορά αντ/κών από το εμπόριο (Απ.Ανάθ.592 Φ.511/10-02-2026) | AF14: 1
A15: 2 | B15: Φεβρουάριος | C15: 5 | D15: Εγγραφή με τ.α.α.2/2026 για αγορά αντ/κών από το εμπόριο (Απ.Ανάθ.523 Φ.511/05-02-2026)
A16: 3 | B16: Φεβρουάριος | C16: 5 | D16: Εγγραφή με τ.α.α.3/2026 για αγορά αντ/κών από το εμπόριο (Απ.Ανάθ.523 Φ.511/05-02-2026) | AF16: 1 | AH16: 1
A17: 4 | B17: Φεβρουάριος | C17: 5 | D17: Εγγραφή με τ.α.α.4/2026 για αγορά αντ/κών από το εμπόριο (Απ.Ανάθ.523 Φ.511/05-02-2026)
A18: 5 | B18: Φεβρουάριος | C18: 6 | D18: Εγγραφή με τ.α.α.6/2026 για αγορά αντ/κών από το εμπόριο (Απ.Ανάθ.523 Φ.511/05-02-2026)
A19: 6 | B19: Φεβρουάριος | C19: 11 | D19: Εγγραφή με τ.α.α.8/2026 για αγορά αντ/κών από το εμπόριο (Απ.Ανάθ.523 Φ.511/05-02-2026)
A20: 7 | B20: Μάρτιος | C20: 27 | D20: Εγγραφή με τ.α.α.9/2026 για αγορά αντ/κών από το εμπόριο (Απ.Ανάλ.Υποχρ.3365 /10-03-2026)
A21: 8 | B21: Φεβρουάριος | C21: 5 | D21: Εγγραφή με τ.α.α.10/2026 για αγορά αντ/κών από το εμπόριο (Απ.Ανάλ.Υποχρ.866/26-01-2026) | AF21: 8
A22: 9 | B22: Μάιος | C22: 5 | D22: Διαγραφή Π.Σ.1116 λόγω απόσυρσης(Δγη 26351 Φ.544.1 05-05-2026) | R22: 1
A23: 10 | B23: Μάιος | C23: 25 | D23: Εγγραφή με τ.α.α.16/2026 για αγορά αντ/κών από το εμπόριο (Απ.Ανάλ.Υποχρ.8409/15-05-2026)
A24: 11 | B24: Μάιος | C24: 26 | D24: Εγγραφή με τ.α.α.18/2026 για αγορά αντ/κών από το εμπόριο (Απ.Ανάλ.Υποχρ.8409/15-05-2026)
A25: 12 | B25: Μάιος | C25: 25 | D25: Εγγραφή με τ.α.α.19/2026 για αγορά αντ/κών από το εμπόριο (Απ.Ανάλ.Υποχρ.8409/15-05-2026) | AF25: 2
A26: 13 | B26: Ιούνιος | C26: 9 | D26: Εγγραφή με τ.α.α.22/2026 για αγορά αντ/κών από το εμπόριο (Απ.Ανάλ.Υποχρ.2303/19-09-2026)
A27: 14 | B27: Ιούνιος | C27: 10 | D27: Εγγραφή με τ.α.α.23/2026 για αγορά αντ/κών από το εμπόριο (Απ.Ανάλ.Υποχρ.8409/15-05-2026) | AN27: 2 | AP27: 2
A28: 15 | B28: Ιούνιος | C28: 10 | D28: Εγγραφή με τ.α.α.24/2026 για αγορά αντ/κών από το εμπόριο (Απ.Ανάλ.Υποχρ.8246/14-05-2026) | AN28: 9 | AP28: 12
A29: 16 | B29: Μάιος | C29: 15 | D29: Εγγραφή με τ.α.α.120 ΥΔΙΠΥΛ για Π.Σ. 5428 (Δγη 2208 Φ.544.1/15-01-2026) | K29: 1 | M29: 1 | O29: 2
A30: 17 | B30: Μάιος | C30: 20 | D30: Εγγραφή με τ.α.α. 984 ΥΔΙΠΥΛ για Π.Σ.5740 και Π.Σ.5741 (Δγη11526/26-06-2026) | K30: 2 | M30: 2 | Q30: 2
A31: 18 | B31: Μάιος | C31: 22 | D31: Εγγραφή με τ.α.α.1655 ΥΔΙΠΥΛ για Π.Σ.5479 (Δγη 12424 Φ.544.1/02-03-2026) | K31: 1 | M31: 1 | O31: 2 | Q31: 1
A32: 19 | B32: Ιούνιος | C32: 19 | D32: Εγγραφή με τ.α.α.26/2026 για αγορά αντ/κών από το εμπόριο (Απ.Ανάλ.Υποχρ.2919/03-03-2026) | AD32: 1 | AF32: 3 | AL32: 1 | AN32: 3 | AP32: 1
A33: 20 | B33: Ιούλιος | C33: 30 | D33: Εγγραφή με τ.α.α.34/2026 για αγορά αντ/κών από το εμπόριο (Απ.Ανάλ.Υποχρ.13759/21-07-2026)
A34: 21 | B34: Ιούλιος | C34: 30 | D34: Εγγραφή με τ.α.α.35/2026 για αγορά αντ/κών από το εμπόριο (Απ.Ανάλ.Υποχρ.13759/21-07-2026)
A35: 22 | B35: Ιούλιος | C35: 30 | D35: Εγγραφή με τ.α.α.37/2026 για αγορά αντ/κών από το εμπόριο (Απ.Ανάλ.Υποχρ.13898/23-07-2026)
A36: 23 | B36: Ιούλιος | C36: 30 | D36: Εγγραφή με τ.α.α.38/2026 για αγορά αντ/κών από το εμπόριο (Απ.Ανάλ.Υποχρ.13898/23-07-2026)
A37: 24 | B37: Ιούλιος | C37: 30 | D37: Εγγραφή με τ.α.α.39/2026 για αγορά αντ/κών από το εμπόριο (Απ.Ανάλ.Υποχρ.13898/23-07-2026)
A38: 25 | B38: Αύγουστος | C38: 3 | D38: Εγγραφή με τ.α.α.42/2026 για αγορά αντ/κών από το εμπόριο (Απ.Ανάλ.Υποχρ.13759/21-07-2026) | AF38: 8
A39: 26 | B39: Αύγουστος | C39: 4 | D39: Εγγραφή με τ.α.α.43/2026 για αγορά αντ/κών από το εμπόριο (Απ.Ανάλ.Υποχρ.13759/21-07-2026) | AH39: 1 | AN39: 2

Sheet ΓΑΗ(34)
A1: ΒΙΒΛΙΟ | X1: ΥΛΙΚΟΥ ΔΙΟΙΚΗΣΗΣ Π.Υ. ΝΟΜΟΥ ΚΕΡΚΥΡΑΣ
A3: Αύξων αριθμός δικαιολογητικών | B3: 2026 | D3: Σελίδα 34 | K3: Δισκόφρενα | M3: Τακάκια Φρένων τροχών | O3: Φίλτρο Πετρελαίου | Q3: Βεντιλατέρ | S3: Χειρολαβές Θυρών Οχημάτων | U3: Ελαστικές Φούσκες-Φυσούνες | X3: Φίλτρα Αεροσυμπιεστή Πλήρωσης ΑΣ Ξήρανσης | Z3: Ατέρμονες Συστήματος Διεύθυνσης | AB3: Βαλβίδες Ελαίου | AD3: Αντλίες Διάφορες Καυσίμων Κινητήρων | AF3: Περικόχλια Τροχών Οχημάτων | AH3: Δοχεία Υγρών Αντλίας Φρένων Διάφορα | AJ3: Διακόπτες Διάφοροι Κινητήρων | AL3: Ανταλλακτικά Διάφορα Κιβωτίου Ταχυτήτων | AN3: Βολάν-Στεφάνες Συστήματος Διευθύνσεως | AP3: Μηχανισμοί Αυτόματοι Ανοίγματος Θυρών Κύστεων
D5: ΛΕΠΤΟΜΕΡΕΙΕΣ
B7: Μήνας | C7: Ημέρα
D8: Αύξων αριθμός ονομαστικού | K8: 261 | M8: 350 | O8: 374 | Q8: 7 | S8: 243α | U8: 67 | X8: 356 | Z8: 30 | AB8: 31 | AD8: 16 | AF8: 108α | AH8: 52 | AJ8: 55 | AL8: 299 | AN8: 43 | AP8: 421
D10: Γ.΄Α.΄Η.΄
D12: ΑΝΤΑΛΛΑΚΤΙΚΑ ΔΙΑΦΟΡΩΝ ΤΥΠΩΝ ΟΧΗΜΑΤΩΝ | K12: Χ | L12: Π | M12: Χ | N12: Π | O12: Χ | P12: Π | Q12: Χ | R12: Π | S12: Χ | T12: Π | U12: Χ | V12: Π | X12: Χ | Y12: Π | Z12: Χ | AA12: Π | AB12: Χ | AC12: Π | AD12: Χ | AE12: Π | AF12: Χ | AG12: Π | AH12: Χ | AI12: Π | AJ12: Χ | AK12: Π | AL12: Χ | AM12: Π | AN12: Χ | AO12: Π | AP12: Χ | AQ12: Π
B13: Ιανουάριος | C13: 1 | D13: Υπόλοιπο από μεταφορά έτους 2023 | K13: 6 | L13: 0 | M13: 14 | N13: 0 | O13: 39 | P13: 0 | Q13: 7 | R13: 0 | S13: 3 | T13: 0 | U13: 12 | V13: 0 | X13: 4 | Y13: 0 | Z13: 3 | AA13: 0 | AB13: 10 | AC13: 0 | AD13: 1 | AE13: 0 | AF13: 13 | AG13: 0 | AH13: 2 | AI13: 0 | AJ13: 7 | AK13: 0 | AL13: 3 | AM13: 0 | AN13: 3 | AO13: 0 | AP13: 14 | AQ13: 0
A14: 1 | U14: 8
A15: 2 | Z15: 1 | AB15: 2
A16: 3
A17: 4 | AD17: 1
A18: 5 | S18: 2 | AN18: 1 | AP18: 3
A19: 6 | U19: 1 | AD19: 1 | AF19: 1
A20: 7
A21: 8 | M21: 2 | O21: 1 | S21: 1 | U21: 4 | AB21: 1
A22: 9
A23: 10 | U23: 1
A24: 11
A25: 12
A26: 13 | AL26: 46
A27: 14 | O27: 2 | U27: 2 | AJ27: 1
A28: 15 | O28: 14 | U28: 2
A29: 16
A30: 17
A31: 18 | O31: 3 | X31: 2 | AB31: 8 | AD31: 1 | AH31: 1 | AN31: 5
A32: 19
A33: 20
A34: 21
A35: 22 | O35: 1
A36: 23
A37: 24
A38: 25
A39: 26 | AF39: 2

Sheet ΓΑΗ(36)
A1: ΒΙΒΛΙΟ | X1: ΥΛΙΚΟΥ ΔΙΟΙΚΗΣΗΣ Π.Υ. ΝΟΜΟΥ ΚΕΡΚΥΡΑΣ
A3: Αύξων αριθμός δικαιολογητικών | B3: 2026 | D3: Σελίδα 36 | K3: Εκκινητήρες - Μίζες | M3: Ανταλλακτικά Αντλίας Ύδατος σε σετ | O3: Γρύλοι Ανύψωσης Υαλοπινάκων Οχημάτων | Q3: Αμορτισέρ Κύστεων Οχημάτων | S3: Τύμπανα Πέδης Εμπρόσθιων Τροχών | U3: Εξαρτήματα Φρένων Σετ | X3: Σύρματα - Ντίζες Μικρές Διαφόρων Οχημάτων | Z3: Διακοσμητικά Καπώ Διάφορα | AB3: Πώματα Ρεζερβουάρ | AD3: Τσιμούχες μετα Ρουλεμάν σε σετ Γενικά | AF3: Ζυγαριές Οχημάτων (Ανταλλακτικά Εμπρόσθιου Συστήματος) | AH3: Ελατήρια Σουστών | AJ3: Μπάρες Τιμονιού σετ | AL3: Ρουλεμάν | AN3: Αμορτισέρ Τροχών | AP3: Αμορτισέρ Κύστεων οχημάτων
D5: ΛΕΠΤΟΜΕΡΕΙΕΣ
B7: Μήνας | C7: Ημέρα
D8: Αύξων αριθμός ονομαστικού | K8: 79 | M8: 27 | O8: 45 | Q8: 237 | S8: 225 | U8: 63 | X8: 178 | Z8: 47 | AB8: 293 | AD8: 360 | AF8: 396 | AH8: 60 | AJ8: 352 | AL8: 199 | AN8: 13 | AP8: 13α
D10: Γ.΄Α.΄Η.΄
D12: ΑΝΤΑΛΛΑΚΤΙΚΑ ΔΙΑΦΟΡΩΝ ΤΥΠΩΝ ΟΧΗΜΑΤΩΝ | K12: Χ | L12: Π | M12: Χ | N12: Π | O12: Χ | P12: Π | Q12: Χ | R12: Π | S12: Χ | T12: Π | U12: Χ | V12: Π | X12: Χ | Y12: Π | Z12: Χ | AA12: Π | AB12: Χ | AC12: Π | AD12: Χ | AE12: Π | AF12: Χ | AG12: Π | AH12: Χ | AI12: Π | AJ12: Χ | AK12: Π | AL12: Χ | AM12: Π | AN12: Χ | AO12: Π | AP12: Χ | AQ12: Π
D13: Υπόλοιπο από μεταφορά έτους 2023 | K13: 3 | L13: 0 | M13: 7 | N13: 0 | O13: 3 | P13: 0 | Q13: 4 | R13: 0 | S13: 2 | T13: 0 | U13: 20 | V13: 0 | X13: 2 | Y13: 0 | Z13: 2 | AA13: 0 | AB13: 2 | AC13: 0 | AD13: 1 | AE13: 0 | AF13: 3 | AG13: 0 | AH13: 8 | AI13: 0 | AJ13: 5 | AK13: 0 | AL13: 13 | AM13: 0 | AN13: 5 | AO13: 0 | AP13: 6 | AQ13: 0
A14: 1 | X14: 6
A15: 2 | Z15: 1
A16: 3
A17: 4
A18: 5 | O18: 4 | Z18: 1
A19: 6
A20: 7 | AF20: 1
A21: 8 | Z21: 5
A22: 9
A23: 10
A24: 11 | M24: 9
A25: 12 | X25: 1 | Z25: 2
A26: 13 | X26: 1 | AL26: 6
A27: 14 | AN27: 4
A28: 15
A29: 16
A30: 17
A31: 18 | M31: 2 | Q31: 1 | Z31: 3 | AJ31: 8 | AL31: 2
A32: 19
A33: 20 | X33: 1 | Z33: 1
A34: 21 | O34: 2
A35: 22
A36: 23 | M36: 1 | Z36: 1
A37: 24 | O37: 3
A38: 25
A39: 26

Sheet ΓΑΗ(38)
A1: ΒΙΒΛΙΟ | X1: ΥΛΙΚΟΥ ΔΙΟΙΚΗΣΗΣ Π.Υ. ΝΟΜΟΥ ΚΕΡΚΥΡΑΣ
A3: Αύξων αριθμός δικαιολογητικών | B3: 2026 | D3: Σελίδα 38 | K3: Διακόπτες Φωτισμού | M3: Βάσεις Πλαστικές Τιμονιού | O3: Βάσεις Σαζμάν | Q3: Βάσεις Μηχανών Οχημάτων εν γένει | S3: Ρυθμιστές Διάφοροι - Ρεγουλατόροι | U3: Σωλήνες Υψηλής πίεσης διαφόρων οχημάτων | X3: Συμπλέκτες πλήρεις οχημάτων | Z3: Δείκτες Ελαίου κινητήρων | AB3: Τούρμπο κινητήρα σε σετ | AD3: Φτερωτές | AF3: Υαλοπίνακες Θυρών Οχημάτων | AH3: Σωλήνες Εξάτμισης Διάφοροι | AJ3: Φωλιές Συνεμπλόκ | AL3: Διακόπτες Ηλεκτρομαγνητικοί Συσσωρευτών | AN3: Σειρές Καθισμάτων-Ανταλλακτικά | AP3: Ταπετσαρίες Οχημάτων
D5: ΛΕΠΤΟΜΕΡΕΙΕΣ
B7: Μήνας | C7: Ημέρα
D8: Αύξων αριθμός ονομαστικού | K8: 455 | M8: 458 | O8: 39 | Q8: 40 | S8: 173α | U8: 188 | X8: 194 | Z8: 319 | AB8: 411 | AD8: 27β | AF8: 229 | AH8: 195 | AJ8: 28γ | AL8: 54 | AN8: 186 | AP8: 89
D10: Γ.΄Α.΄Η.΄
D12: ΑΝΤΑΛΛΑΚΤΙΚΑ ΔΙΑΦΟΡΩΝ ΤΥΠΩΝ ΟΧΗΜΑΤΩΝ | K12: Χ | L12: Π | M12: Χ | N12: Π | O12: Χ | P12: Π | Q12: Χ | R12: Π | S12: Χ | T12: Π | U12: Χ | V12: Π | X12: Χ | Y12: Π | Z12: Χ | AA12: Π | AB12: Χ | AC12: Π | AD12: Χ | AE12: Π | AF12: Χ | AG12: Π | AH12: Χ | AI12: Π | AJ12: Χ | AK12: Π | AL12: Χ | AM12: Π | AN12: Χ | AO12: Π | AP12: Χ | AQ12: Π
D13: Υπόλοιπο από μεταφορά έτους 2023 | K13: 2 | L13: 0 | M13: 11 | N13: 0 | O13: 4 | P13: 0 | Q13: 8 | R13: 0 | S13: 4 | T13: 0 | U13: 11 | V13: 0 | X13: 3 | Y13: 0 | Z13: 2 | AA13: 0 | AB13: 2 | AC13: 0 | AD13: 6 | AE13: 0 | AF13: 1 | AG13: 0 | AH13: 0 | AI13: 0 | AJ13: 0 | AK13: 0 | AL13: 0 | AM13: 0 | AN13: 0 | AO13: 0 | AP13: 0 | AQ13: 0
A14: 1 | Q14: 1 | X14: 1 | AB14: 1
A15: 2
A16: 3
A17: 4
A18: 5 | AF18: 2 | AP18: 3
A19: 6
A20: 7
A21: 8 | X21: 1
A22: 9
A23: 10 | K23: 1
A24: 11
A25: 12
A26: 13
A27: 14
A28: 15 | U28: 3 | AL28: 7
A29: 16
A30: 17
A31: 18 | U31: 2 | AJ31: 8
A32: 19
A33: 20 | Z33: 4
A34: 21
A35: 22 | U35: 1
A36: 23
A37: 24
A38: 25
A39: 26 | S39: 1 | U39: 1

Sheet ΓΑΗ(40)
A1: ΒΙΒΛΙΟ | X1: ΥΛΙΚΟΥ ΔΙΟΙΚΗΣΗΣ Π.Υ. ΝΟΜΟΥ ΚΕΡΚΥΡΑΣ
A3: Αύξων αριθμός δικαιολογητικών | B3: 2026 | D3: Σελίδα 40 | K3: Αερόσακοι Οχημάτων | M3: Φίλτρο Βρενζίνης | O3: Ακουστικά Μηχανών
D5: ΛΕΠΤΟΜΕΡΕΙΕΣ
B7: Μήνας | C7: Ημέρα
D8: Αύξων αριθμός ονομαστικού | K8: 460 | M8: 232 | O8: 404
D10: Γ.΄Α.΄Η.΄
D12: ΑΝΤΑΛΛΑΚΤΙΚΑ ΔΙΑΦΟΡΩΝ ΤΥΠΩΝ ΟΧΗΜΑΤΩΝ | K12: Χ | L12: Π | M12: Χ | N12: Π | O12: Χ | P12: Π | Q12: Χ | R12: Π | S12: Χ | T12: Π | U12: Χ | V12: Π | X12: Χ | Y12: Π | Z12: Χ | AA12: Π | AB12: Χ | AC12: Π | AD12: Χ | AE12: Π | AF12: Χ | AG12: Π | AH12: Χ | AI12: Π | AJ12: Χ | AK12: Π | AL12: Χ | AM12: Π | AN12: Χ | AO12: Π | AP12: Χ | AQ12: Π
D13: Υπόλοιπο από μεταφορά έτους 2023 | K13: 0 | L13: 0 | M13: 0 | N13: 0 | O13: 0 | P13: 0
A14: 1
A15: 2
A16: 3
A17: 4
A18: 5
A19: 6
A20: 7
A21: 8
A22: 9
A23: 10
A24: 11
A25: 12
... A27: 14
A28: 15 | M28: 3
A29: 16
A30: 17
A31: 18
A32: 19
A33: 20
A34: 21
A35: 22
A36: 23
A37: 24
A38: 25
A39: 26

Sheet ΓΑΗ(42)
A1: ΒΙΒΛΙΟ | X1: ΥΛΙΚΟΥ ΔΙΟΙΚΗΣΗΣ Π.Υ. ΝΟΜΟΥ ΚΕΡΚΥΡΑΣ
A3: Αύξων αριθμός δικαιολογητικών | B3: 2026 | D3: Σελίδα 42 | K3: Αντιολισθητικές αλυσίδες σε ζεύγη | M3: Βιβλία οδηγιών χρήσης & συντήρησης οχημάτων | O3: Τάκοι ακινητοποίησης διάφοροι | Q3: Εφεδρικοί τροχοί οχημάτων | S3: Πλαστικές δεξαμενές | U3: Πλαστικές δεξαμενές | X3: Τάπα πλεύσης για το ερπιστρυοφόρο BV-206 | Z3: Σειρά εργαλείων και ανταλακτικών αντλίας BMW του ΠΣ 2454 | AB3: Ερπύστριες | AD3: Αντλίες Ύδατος Κινητήρων | AF3: Δακτύλιοι Ελαστικοί Διάφοροι | AH3: Ιμάντες Ανεμιστήρων-Βεντιλατέρ | AJ3: Κλειδαριές Οχημάτων Γενικά | AL3: Σιαγόνες Πέδησης Οχημάτων πλήρης σε ζεύγη | AN3: Φίλτρα Ελαίου Διαφόρων Οχημάτων | AP3: Φίλτρα Αέρος Διαφόρων Οχημάτων
D5: ΛΕΠΤΟΜΕΡΕΙΕΣ
B7: Μήνας | C7: Ημέρα
D8: Αύξων αριθμός ονομαστικού | K8: 11 | M8: 35 | O8: 197 | Q8: 220 | S8: 418 | U8: 418α | X8: 431 | Z8: 452 | AB8: 465 | AD8: 18 | AF8: 50 | AH8: 109 | AJ8: 127 | AL8: 189 | AN8: 230 | AP8: 233
D10: Γ.΄Α.΄Η.΄
D12: ΑΝΤΑΛΛΑΚΤΙΚΑ ΔΙΑΦΟΡΩΝ ΤΥΠΩΝ ΟΧΗΜΑΤΩΝ | K12: Χ | L12: Π | M12: Χ | N12: Π | O12: Χ | P12: Π | Q12: Χ | R12: Π | S12: Χ | T12: Π | U12: Χ | V12: Π | X12: Χ | Y12: Π | Z12: Χ | AA12: Π | AB12: Χ | AC12: Π | AD12: Χ | AE12: Π | AF12: Χ | AG12: Π | AH12: Χ | AI12: Π | AJ12: Χ | AK12: Π | AL12: Χ | AM12: Π | AN12: Χ | AO12: Π | AP12: Χ | AQ12: Π
D13: Υπόλοιπο από μεταφορά έτους 2023 | K13: ='ΓΑΗ(32)'!K54 -> 0 | L13: ='ΓΑΗ(32)'!L54 -> 0 | M13: ='ΓΑΗ(32)'!M54 -> 0 | N13: ='ΓΑΗ(32)'!N54 -> 0 | O13: ='ΓΑΗ(32)'!O54 -> 0 | P13: ='ΓΑΗ(32)'!P54 -> 0 | Q13: ='ΓΑΗ(32)'!Q54 -> 0 | R13: ='ΓΑΗ(32)'!R54 -> 0 | ... V13: ='ΓΑΗ(32)'!V54 -> 0 | X13: ='ΓΑΗ(32)'!X54 -> 0 | Y13: ='ΓΑΗ(32)'!Y54 -> 0 | Z13: ='ΓΑΗ(32)'!Z54 -> 0 | AA13: ='ΓΑΗ(32)'!AA54 -> 0 | AB13: ='ΓΑΗ(32)'!AB54 -> 0 | AC13: ='ΓΑΗ(32)'!AC54 -> 0 | AD13: ='ΓΑΗ(32)'!AD54 -> 0 | AE13: ='ΓΑΗ(32)'!AE54 -> 0 | ... AQ13: ='ΓΑΗ(32)'!AQ54 -> 0

Sheet ΓΑΗ(44)
A1: ΒΙΒΛΙΟ | X1: ΥΛΙΚΟΥ ΔΙΟΙΚΗΣΗΣ Π.Υ. ΝΟΜΟΥ ΚΕΡΚΥΡΑΣ
A3: Αύξων αριθμός δικαιολογητικών | B3: 2026 | D3: Σελίδα 44 | K3: Δισκόφρενα | M3: Τακάκια Φρένων τροχών | O3: Φίλτρο Πετρελαίου | Q3: Βεντιλατέρ | S3: Χειρολαβές Θυρών Οχημάτων | U3: Ελαστικές Φούσκες-Φυσούνες | X3: Φίλτρα Αεροσυμπιεστή Πλήρωσης ΑΣ Ξήρανσης | Z3: Ατέρμονες Συστήματος Διεύθυνσης | AB3: Βαλβίδες Ελαίου | AD3: Αντλίες Διάφορες Καυσίμων Κινητήρων | AF3: Περικόχλια Τροχών Οχημάτων | AH3: Δοχεία Υγρών Αντλίας Φρένων Διάφορα | AJ3: Διακόπτες Διάφοροι Κινητήρων | AL3: Ανταλλακτικά Διάφορα Κιβωτίου Ταχυτήτων | AN3: Βολάν-Στεφάνες Συστήματος Διευθύνσεως | AP3: Μηχανισμοί Αυτόματοι Ανοίγματος Θυρών Κύστεων
D5: ΛΕΠΤΟΜΕΡΕΙΕΣ
B7: Μήνας | C7: Ημέρα
D8: Αύξων αριθμός ονομαστικού | K8: 261 | M8: 350 | O8: 374 | Q8: 7 | S8: 243α | U8: 67 | X8: 356 | Z8: 30 | AB8: 31 | AD8: 16 | AF8: 108α | AH8: 52 | AJ8: 55 | AL8: 299 | AN8: 43 | AP8: 421
D10: Γ.΄Α.΄Η.΄
D12: ΑΝΤΑΛΛΑΚΤΙΚΑ ΔΙΑΦΟΡΩΝ ΤΥΠΩΝ ΟΧΗΜΑΤΩΝ | K12: Χ | L12: Π | M12: Χ | N12: Π | O12: Χ | P12: Π | Q12: Χ | R12: Π | S12: Χ | T12: Π | U12: Χ | V12: Π | X12: Χ | Y12: Π | Z12: Χ | AA12: Π | AB12: Χ | AC12: Π | AD12: Χ | AE12: Π | AF12: Χ | AG12: Π | AH12: Χ | AI12: Π | AJ12: Χ | AK12: Π | AL12: Χ | AM12: Π | AN12: Χ | AO12: Π | AP12: Χ | AQ12: Π
D13: Υπόλοιπο από μεταφορά έτους 2023 | K13: ='ΓΑΗ(34)'!K54 -> 0 | L13: ='ΓΑΗ(34)'!L54 -> 0 | M13: ='ΓΑΗ(34)'!M54 -> 0 | N13: ='ΓΑΗ(34)'!N54 -> 0 | O13: ='ΓΑΗ(34)'!O54 -> 0 | P13: ='ΓΑΗ(34)'!P54 -> 0 | Q13: ='ΓΑΗ(34)'!Q54 -> 0 | R13: ='ΓΑΗ(34)'!R54 -> 0 | ... V13: ='ΓΑΗ(34)'!V54 -> 0 | X13: ='ΓΑΗ(34)'!X54 -> 0 | Y13: ='ΓΑΗ(34)'!Y54 -> 0 | Z13: ='ΓΑΗ(34)'!Z54 -> 0 | AA13: ='ΓΑΗ(34)'!AA54 -> 0 | AB13: ='ΓΑΗ(34)'!AB54 -> 0 | AC13: ='ΓΑΗ(34)'!AC54 -> 0 | AD13: ='ΓΑΗ(34)'!AD54 -> 0 | AE13: ='ΓΑΗ(34)'!AE54 -> 0 | ... AQ13: ='ΓΑΗ(34)'!AQ54 -> 0

Sheet ΓΑΗ(46)
A1: ΒΙΒΛΙΟ | X1: ΥΛΙΚΟΥ ΔΙΟΙΚΗΣΗΣ Π.Υ. ΝΟΜΟΥ ΚΕΡΚΥΡΑΣ
A3: Αύξων αριθμός δικαιολογητικών | B3: 2026 | D3: Σελίδα 46 | K3: Εκκινητήρες - Μίζες | M3: Ανταλλακτικά Αντλίας Ύδατος σε σετ | O3: Γρύλοι Ανύψωσης Υαλοπινάκων Οχημάτων | Q3: Αμορτισέρ Κύστεων Οχημάτων | S3: Τύμπανα Πέδης Εμπρόσθιων Τροχών | U3: Εξαρτήματα Φρένων Σετ | X3: Σύρματα - Ντίζες Μικρές Διαφόρων Οχημάτων | Z3: Διακοσμητικά Καπώ Διάφορα | AB3: Πώματα Ρεζερβουάρ | AD3: Τσιμούχες μετα Ρουλεμάν σε σετ Γενικά | AF3: Ζυγαριές Οχημάτων (Ανταλλακτικά Εμπρόσθιου Συστήματος) | AH3: Ελατήρια Σουστών | AJ3: Μπάρες Τιμονιού σετ | AL3: Ρουλεμάν | AN3: Αμορτισέρ Τροχών | AP3: Αμορτισέρ Κύστεων οχημάτων
D5: ΛΕΠΤΟΜΕΡΕΙΕΣ
B7: Μήνας | C7: Ημέρα
D8: Αύξων αριθμός ονομαστικού | K8: 79 | M8: 27 | O8: 45 | Q8: 237 | S8: 225 | U8: 63 | X8: 178 | Z8: 47 | AB8: 293 | AD8: 360 | AF8: 396 | AH8: 60 | AJ8: 352 | AL8: 199 | AN8: 13 | AP8: 13α
D10: Γ.΄Α.΄Η.΄
D12: ΑΝΤΑΛΛΑΚΤΙΚΑ ΔΙΑΦΟΡΩΝ ΤΥΠΩΝ ΟΧΗΜΑΤΩΝ | K12: Χ | L12: Π | M12: Χ | N12: Π | O12: Χ | P12: Π | Q12: Χ | R12: Π | S12: Χ | T12: Π | U12: Χ | V12: Π | X12: Χ | Y12: Π | Z12: Χ | AA12: Π | AB12: Χ | AC12: Π | AD12: Χ | AE12: Π | AF12: Χ | AG12: Π | AH12: Χ | AI12: Π | AJ12: Χ | AK12: Π | AL12: Χ | AM12: Π | AN12: Χ | AO12: Π | AP12: Χ | AQ12: Π
D13: Υπόλοιπο από μεταφορά έτους 2023 | K13: ='ΓΑΗ(36)'!K54 -> 0 | L13: ='ΓΑΗ(36)'!L54 -> 0 | M13: ='ΓΑΗ(36)'!M54 -> 0 | N13: ='ΓΑΗ(36)'!N54 -> 0 | O13: ='ΓΑΗ(36)'!O54 -> 0 | P13: ='ΓΑΗ(36)'!P54 -> 0 | Q13: ='ΓΑΗ(36)'!Q54 -> 0 | R13: ='ΓΑΗ(36)'!R54 -> 0 | ... V13: ='ΓΑΗ(36)'!V54 -> 0 | X13: ='ΓΑΗ(36)'!X54 -> 0 | Y13: ='ΓΑΗ(36)'!Y54 -> 0 | Z13: ='ΓΑΗ(36)'!Z54 -> 0 | AA13: ='ΓΑΗ(36)'!AA54 -> 0 | AB13: ='ΓΑΗ(36)'!AB54 -> 0 | AC13: ='ΓΑΗ(36)'!AC54 -> 0 | AD13: ='ΓΑΗ(36)'!AD54 -> 0 | AE13: ='ΓΑΗ(36)'!AE54 -> 0 | ... AQ13: ='ΓΑΗ(36)'!AQ54 -> 0

Sheet ΓΑΗ(48)
A1: ΒΙΒΛΙΟ | X1: ΥΛΙΚΟΥ ΔΙΟΙΚΗΣΗΣ Π.Υ. ΝΟΜΟΥ ΚΕΡΚΥΡΑΣ
A3: Αύξων αριθμός δικαιολογητικών | B3: 2026 | D3: Σελίδα 48 | K3: Διακόπτες Φωτισμού | M3: Βάσεις Πλαστικές Τιμονιού | O3: Βάσεις Σαζμάν | Q3: Βάσεις Μηχανών Οχημάτων εν γένει | S3: Ρυθμιστές Διάφοροι - Ρεγουλατόροι | U3: Σωλήνες Υψηλής πίεσης διαφόρων οχημάτων | X3: Συμπλέκτες πλήρεις οχημάτων | Z3: Δείκτες Ελαίου κινητήρων | AB3: Τούρμπο κινητήρα σε σετ | AD3: Φτερωτές | AF3: Υαλοπίνακες Θυρών Οχημάτων | AH3: Σωλήνες Εξάτμισης Διάφοροι | AJ3: Φωλιές Συνεμπλόκ | AL3: Διακόπτες Ηλεκτρομαγνητικοί Συσσωρευτών | AN3: Σειρές Καθισμάτων-Ανταλλακτικά | AP3: Ταπετσαρίες Οχημάτων
D5: ΛΕΠΤΟΜΕΡΕΙΕΣ
B7: Μήνας | C7: Ημέρα
D8: Αύξων αριθμός ονομαστικού | K8: 455 | M8: 458 | O8: 39 | Q8: 40 | S8: 173α | U8: 188 | X8: 194 | Z8: 319 | AB8: 411 | AD8: 27β | AF8: 229 | AH8: 195 | AJ8: 28γ | AL8: 54 | AN8: 186 | AP8: 89
D10: Γ.΄Α.΄Η.΄
D12: ΑΝΤΑΛΛΑΚΤΙΚΑ ΔΙΑΦΟΡΩΝ ΤΥΠΩΝ ΟΧΗΜΑΤΩΝ | K12: Χ | L12: Π | M12: Χ | N12: Π | O12: Χ | P12: Π | Q12: Χ | R12: Π | S12: Χ | T12: Π | U12: Χ | V12: Π | X12: Χ | Y12: Π | Z12: Χ | AA12: Π | AB12: Χ | AC12: Π | AD12: Χ | AE12: Π | AF12: Χ | AG12: Π | AH12: Χ | AI12: Π | AJ12: Χ | AK12: Π | AL12: Χ | AM12: Π | AN12: Χ | AO12: Π | AP12: Χ | AQ12: Π
D13: Υπόλοιπο από μεταφορά έτους 2023 | K13: ='ΓΑΗ(38)'!K54 -> 0 | L13: ='ΓΑΗ(38)'!L54 -> 0 | M13: ='ΓΑΗ(38)'!M54 -> 0 | N13: ='ΓΑΗ(38)'!N54 -> 0 | O13: ='ΓΑΗ(38)'!O54 -> 0 | P13: ='ΓΑΗ(38)'!P54 -> 0 | Q13: ='ΓΑΗ(38)'!Q54 -> 0 | R13: ='ΓΑΗ(38)'!R54 -> 0 | ... V13: ='ΓΑΗ(38)'!V54 -> 0 | X13: ='ΓΑΗ(38)'!X54 -> 0 | Y13: ='ΓΑΗ(38)'!Y54 -> 0 | Z13: ='ΓΑΗ(38)'!Z54 -> 0 | AA13: ='ΓΑΗ(38)'!AA54 -> 0 | AB13: ='ΓΑΗ(38)'!AB54 -> 0 | AC13: ='ΓΑΗ(38)'!AC54 -> 0 | AD13: ='ΓΑΗ(38)'!AD54 -> 0 | AE13: ='ΓΑΗ(38)'!AE54 -> 0 | ... AQ13: ='ΓΑΗ(38)'!AQ54 -> 0

Sheet ΓΑΗ(50)
A1: ΒΙΒΛΙΟ | X1: ΥΛΙΚΟΥ ΔΙΟΙΚΗΣΗΣ Π.Υ. ΝΟΜΟΥ ΚΕΡΚΥΡΑΣ
A3: Αύξων αριθμός δικαιολογητικών | B3: 2026 | D3: Σελίδα 50 | K3: Αερόσακοι Οχημάτων | M3: Φίλτρο Βρενζίνης | O3: Ακουστικά Μηχανών
D5: ΛΕΠΤΟΜΕΡΕΙΕΣ
B7: Μήνας | C7: Ημέρα
D8: Αύξων αριθμός ονομαστικού | K8: 460 | M8: 232 | O8: 404
D10: Γ.΄Α.΄Η.΄
D12: ΑΝΤΑΛΛΑΚΤΙΚΑ ΔΙΑΦΟΡΩΝ ΤΥΠΩΝ ΟΧΗΜΑΤΩΝ | K12: Χ | L12: Π | M12: Χ | N12: Π | O12: Χ | P12: Π | Q12: Χ | R12: Π | S12: Χ | T12: Π | U12: Χ | V12: Π | X12: Χ | Y12: Π | Z12: Χ | AA12: Π | AB12: Χ | AC12: Π | AD12: Χ | AE12: Π | AF12: Χ | AG12: Π | AH12: Χ | AI12: Π | AJ12: Χ | AK12: Π | AL12: Χ | AM12: Π | AN12: Χ | AO12: Π | AP12: Χ | AQ12: Π
D13: Υπόλοιπο από μεταφορά έτους 2023 | K13: ='ΓΑΗ(40)'!K54 -> 0 | L13: ='ΓΑΗ(40)'!L54 -> 0 | M13: ='ΓΑΗ(40)'!M54 -> 0 | N13: ='ΓΑΗ(40)'!N54 -> 0 | O13: 0 | P13: 0

Sheet ΓΑΘ(52)
A1: ΒΙΒΛΙΟ | X1: ΥΛΙΚΟΥ ΔΙΟΙΚΗΣΗΣ Π.Υ. ΝΟΜΟΥ ΚΕΡΚΥΡΑΣ
A3: Αύξων αριθμός δικαιολογητικών | B3: 2026 | D3: Σελίδα 52 | K3: Βαλβολινιέρα | M3: Λαδικό | O3: Πρέσσες λίπανσης (γρασσαδόρος) αεροκινουμενες | Q3: Γρασαδόροι χειρός | S3: Χειραντλία αναρρόφησης ελαίου κινητήρων | U3: Λιπαντήρες Τροχήλατου Αεροσυμπιεστού
D5: ΛΕΠΤΟΜΕΡΕΙΕΣ
B7: Μήνας | C7: Ημέρα
D8: Αύξων αριθμός ονομαστικού | K8: 1α | M8: 4 | O8: 10 | Q8: 18 | S8: 20 | U8: 19
D10: Γ.΄Α.΄Θ.΄
D12: ΕΡΓΑΛΕΙΑ ΟΧΗΜΑΤΩΝ ΕΝ ΓΕΝΕΙ | K12: Χ | L12: Π | M12: Χ | N12: Π | O12: Χ | P12: Π | Q12: Χ | R12: Π | S12: Χ | T12: Π | U12: Χ | V12: Π | X12: Χ | Y12: Π | Z12: Χ | AA12: Π | AB12: Χ | AC12: Π | AD12: Χ | AE12: Π | AF12: Χ | AG12: Π | AH12: Χ | AI12: Π | AJ12: Χ | AK12: Π | AL12: Χ | AM12: Π | AN12: Χ | AO12: Π | AP12: Χ | AQ12: Π
B13: Ιανουάριος | C13: 1 | D13: Υπόλοιπο από μεταφορά έτους 2023 | K13: 1 | L13: 0 | M13: 1 | N13: 0 | O13: 1 | P13: 0 | Q13: 18 | R13: 0 | S13: 1 | T13: 0 | U13: 1 | V13: 0
A14: 1 | B14: Μάιος | C14: 22 | D14: Εγγραφή με τ.α.α.1656 ΥΔΙΠΥΛ για Π.Σ.5479 (Δγη 12424 Φ.544.1/02-03-2026) | Q14: 1

Sheet ΓΑΙ(54)
A1: ΒΙΒΛΙΟ | X1: ΥΛΙΚΟΥ ΔΙΟΙΚΗΣΗΣ Π.Υ. ΝΟΜΟΥ ΚΕΡΚΥΡΑΣ
A3: Αύξων αριθμός δικαιολογητικών | B3: 2026 | D3: Σελίδα 54 | K3: Βαλβολίνη σε χιλιόγραμμα | M3: Βενζίνη ΑΜΟΛΥΒΔΗ σε λίτρα | O3: Λίπος (Γράσο) σε χιλιόγραμμα | Q3: Ορυκτέλαιο σε χιλιόγραμμα | S3: Ορυκτέλαιο Υψηλών Πιέσεων σε χιλιόγραμμα | U3: DIESEL Κίνησης | X3: Ταινίες μονωτικές | Z3: Υγρά Φρένων | AB3: Αντιψυκτικό | AD3: Απιονισμένο νερό σε λίτρα | AF3: DIESEL Θέρμανσης | AH3: Λάδι κινητήρα Αεροσυμπιεστή σε λίτρα | AJ3: Ταινία προστασιας διαχωριστική | AL3: Λάδι Μείγμα | AN3: Ενισχυτικό καυσίμων "AD BLUE" σε λίτρα | AP3: Αεροπορικά Καύσιμα
D5: ΛΕΠΤΟΜΕΡΕΙΕΣ
B7: Μήνας | C7: Ημέρα
D8: Αύξων αριθμός ονομαστικού | K8: 15 | M8: 17β | O8: 66 | Q8: 95 | S8: 96 | U8: 105 | X8: 144 | Z8: 150 | AB8: 153 | AD8: 158α | AF8: 186 | AH8: 208 | AJ8: 252 | AL8: 283 | AN8: 296 | AP8: 285
D10: Γ.΄Α.΄Ι.΄
D12: ΔΙΑΦΟΡΕΣ ΥΛΕΣ ΑΝΑΛΩΣΙΜΑ | K12: Χ | L12: Π | M12: Χ | N12: Π | O12: Χ | P12: Π | Q12: Χ | R12: Π | S12: Χ | T12: Π | U12: Χ | V12: Π | X12: Χ | Y12: Π | Z12: Χ | AA12: Π | AB12: Χ | AC12: Π | AD12: Χ | AE12: Π | AF12: Χ | AG12: Π | AH12: Χ | AI12: Π | AJ12: Χ | AK12: Π | AL12: Χ | AM12: Π | AN12: Χ | AO12: Π | AP12: Χ | AQ12: Π
B13: Ιανουάριος | C13: 1 | D13: Υπόλοιπο από μεταφορά έτους 2023 | K13: 200 | L13: 0 | M13: 3370.03 | N13: 0 | O13: 0 | P13: 0 | Q13: 1320 | R13: 0 | S13: 44 | T13: 0 | U13: 57476 | V13: 0 | X13: 0 | Y13: 0 | Z13: 100 | AA13: 0 | AB13: 650 | AC13: 0 | AD13: 40 | AE13: 0 | AF13: 14187 | AG13: 0 | AH13: 28 | AI13: 0 | AJ13: 0 | AK13: 0 | AL13: 28 | AM13: 0 | AN13: 840 | AO13: 0 | AP13: 3617 | AQ13: 0
A14: 1 | B14: Φεβρουάριος | C14: 17 | D14: Διαγραφή καυσίμων Φεβρουάριος 2024 (Δγη 9000 Φ.553.4/17-02-2025) | N14: 188 | R14: 26 | V14: 2773 | AO14: 30
A15: 2 | B15: Μάρτιος | C15: 10 | D15: Διαγραφή καυσίμων Μάρτιος 2024 (Δγη 14546 Φ.553.4/10-03-2026) | N15: 315 | R15: 52 | V15: 3856 | AO15: 10
A16: 3 | B16: Μάρτιος | C16: 20 | D16: Διαγραφή καυσίμων Απρίλιος 2024 (Δγη 15734 Φ.553.4/20-03-2026) | N16: 123 | R16: 112 | V16: 3905 | AO16: 10
A17: 4 | B17: Μάρτιος | C17: 24 | D17: Διαγραφή καυσίμων Μάιος 2024 (Δγη 17542 Φ.553.4/24-03-2026) | N17: 282 | R17: 86 | V17: 3860 | AO17: 20
A18: 5 | B18: Μάρτιος | C18: 24 | D18: Διαγραφή καυσίμων Ιούνιος 2024 (Δγη 17636 Φ.553.4/24-03-2026) | N18: 185 | V18: 3100 | AC18: 10
A19: 6 | B19: Μάρτιος | C19: 31 | D19: Διαγραφή καυσίμων Ιούλιος 2024 (Δγη 18949 Φ.553.4/31-03-2026) | N19: 125 | V19: 6000 | AO19: 50
A20: 7 | B20: Απρίλιος | C20: 1 | D20: Διαγραφή καυσίμων Αύγουστος 2024 (Δγη 19166 Φ.553.4/01-04-2026) | N20: 310 | V20: 7130 | AO20: 90
A21: 8 | B21: Απρίλιος | C21: 1 | D21: Διαγραφή καυσίμων σε ξένες Υπηρεσίες Μάιος 2024 (Δγη 47350 Φ.553.4/02-02-2026) | N21: 172
A22: 9 | B22: Απρίλιος | C22: 1 | D22: Διαγραφή καυσίμων σε ξένες Υπηρεσίες Ιούνιος 2024 (Δγη 47351 Φ.553.4/02-02-2026) | N22: 92
A23: 10 | B23: Απρίλιος | C23: 1 | D23: Διαγραφή καυσίμων σε ξένες Υπηρεσίες Νοέμβριος 2024 (Δγη 53153 Φ.553.4/02-03-2026) | N23: 30
A24: 11 | B24: Απρίλιος | C24: 1 | D24: Διαγραφή καυσίμων σε ξένες Υπηρεσίες Δεκέμβριος 2024 (Δγη 53158 Φ.553.4/02-03-2026) | N24: 68
A25: 12 | B25: Μάιος | C25: 15 | D25: Εγγραφή με τ.α.α.37 ΔΙΠΥΝ Ιωαννίνων για κάυσιμα σε διερχόμενο όχημα | U25: 115
A26: 13 | B26: Μάιος | C26: 15 | D26: Εγγραφή με τ.α.α.09 ΔΙΠΥΝ Ιωαννίνων για καύσιμα από τον Στρατό | U26: 8100
A27: 14 | B27: Μάιος | C27: 15 | D27: Εγγραφή με τ.α.α.25 ΔΙΠΥ Αθηνών για καύσιμα σε διερχόμενο όχημα | U27: 352
A28: 15 | B28: Μάιος | C28: 15 | D28: Εγγραφή με τ.α.α.39 1ης ΕΜΑΚ για καύσιμα σε διερχόμενο όχημα | U28: 168
A29: 16 | B29: Ιούνιος | C29: 15 | D29: Εγγραφή με τ.α.α.56 ΔΙΠΥΝ Ιωαννίνων για κάυσιμα από το Στρατό | M29: 2981 | U29: 7000
A30: 17 | B30: Ιούλιος | C30: 3 | D30: Εγγραφή με τ.α.α.132 ΔΙΠΥ Αθηνών για καύσιμα σε διερχόμενο όχημα | U30: 181
A31: 18 | B31: Ιούλιος | C31: 30 | D31: Εγγραφή με τ.α.α.93 1ης ΕΜΑΚ για καύσιμα σε διερχόμενο όχημα | U31: 43

Sheet ΓΑΙ(56)
A1: ΒΙΒΛΙΟ | X1: ΥΛΙΚΟΥ ΔΙΟΙΚΗΣΗΣ Π.Υ. ΝΟΜΟΥ ΚΕΡΚΥΡΑΣ
A3: Αύξων αριθμός δικαιολογητικών | B3: 2026 | D3: Σελίδα 56
D5: ΛΕΠΤΟΜΕΡΕΙΕΣ
B7: Μήνας | C7: Ημέρα
D8: Αύξων αριθμός ονομαστικού
D10: Γ.΄Α.΄Ι.΄
D12: ΔΙΑΦΟΡΕΣ ΥΛΕΣ ΑΝΑΛΩΣΙΜΑ | K12: Χ | L12: Π | M12: Χ | N12: Π | O12: Χ | P12: Π | Q12: Χ | R12: Π | S12: Χ | T12: Π | U12: Χ | V12: Π | X12: Χ | Y12: Π | Z12: Χ | AA12: Π | AB12: Χ | AC12: Π | AD12: Χ | AE12: Π | AF12: Χ | AG12: Π | AH12: Χ | AI12: Π | AJ12: Χ | AK12: Π | AL12: Χ | AM12: Π | AN12: Χ | AO12: Π | AP12: Χ | AQ12: Π
D13: Υπόλοιπο από μεταφορά έτους 2023

Sheet ΓΑΙ(58)
A1: ΒΙΒΛΙΟ | X1: ΥΛΙΚΟΥ ΔΙΟΙΚΗΣΗΣ Π.Υ. ΝΟΜΟΥ ΚΕΡΚΥΡΑΣ
A3: Αύξων αριθμός δικαιολογητικών | B3: 2026 | D3: Σελίδα 58 | K3: Βαλβολίνη σε χιλιόγραμμα | M3: Βενζίνη ΑΜΟΛΥΒΔΗ σε λίτρα | O3: Λίπος (Γράσο) σε χιλιόγραμμα | Q3: Ορυκτέλαιο σε χιλιόγραμμα | S3: Ορυκτέλαιο Υψηλών Πιέσεων σε χιλιόγραμμα | U3: DIESEL Κίνησης | X3: Ταινίες μονωτικές | Z3: Υγρά Φρένων | AB3: Αντιψυκτικό | AD3: Απιονισμένο νερό σε λίτρα | AF3: DIESEL Θέρμανσης | AH3: Λάδι κινητήρα Αεροσυμπιεστή σε λίτρα | AJ3: Ταινία προστασιας διαχωριστική | AL3: Λάδι Μείγμα | AN3: Ενισχυτικό καυσίμων "AD BLUE" σε λίτρα | AP3: Αεροπορικά Καύσιμα
D5: ΛΕΠΤΟΜΕΡΕΙΕΣ
B7: Μήνας | C7: Ημέρα
D8: Αύξων αριθμός ονομαστικού | K8: 15 | M8: 17β | O8: 66 | Q8: 95 | S8: 96 | U8: 105 | X8: 144 | Z8: 150 | AB8: 153 | AD8: 158α | AF8: 186 | AH8: 208 | AJ8: 252 | AL8: 283 | AN8: 296 | AP8: 285
D10: Γ.΄Α.΄Ι.΄
D12: ΔΙΑΦΟΡΕΣ ΥΛΕΣ ΑΝΑΛΩΣΙΜΑ | K12: Χ | L12: Π | M12: Χ | N12: Π | O12: Χ | P12: Π | Q12: Χ | R12: Π | S12: Χ | T12: Π | U12: Χ | V12: Π | X12: Χ | Y12: Π | Z12: Χ | AA12: Π | AB12: Χ | AC12: Π | AD12: Χ | AE12: Π | AF12: Χ | AG12: Π | AH12: Χ | AI12: Π | AJ12: Χ | AK12: Π | AL12: Χ | AM12: Π | AN12: Χ | AO12: Π | AP12: Χ | AQ12: Π
B13: Ιανουάριος | C13: 1 | D13: Υπόλοιπο από μεταφορά έτους 2023 | K13: 517 | L13: 0 | M13: 5943 | N13: 0 | O13: 108 | P13: 0 | Q13: 2229 | R13: 0 | S13: -6 | T13: 0 | U13: 66790 | V13: 0 | X13: 0 | Y13: 0 | Z13: 256 | AA13: 0 | AB13: 996 | AC13: 0 | AD13: 140 | AE13: 0 | AF13: 17572 | AG13: 0 | AH13: 28 | AI13: 0 | AJ13: 0 | AK13: 0 | AL13: 48 | AM13: 0 | AN13: 990 | AO13: 0 | AP13: 3617 | AQ13: 0

Sheet ΓΑΙ(60)
A1: ΒΙΒΛΙΟ | X1: ΥΛΙΚΟΥ ΔΙΟΙΚΗΣΗΣ Π.Υ. ΝΟΜΟΥ ΚΕΡΚΥΡΑΣ
A3: Αύξων αριθμός δικαιολογητικών | B3: 2026 | D3: Σελίδα 60
D5: ΛΕΠΤΟΜΕΡΕΙΕΣ
B7: Μήνας | C7: Ημέρα
D8: Αύξων αριθμός ονομαστικού
D10: Γ.΄Α.΄Ι.΄
D12: ΔΙΑΦΟΡΕΣ ΥΛΕΣ ΑΝΑΛΩΣΙΜΑ | K12: Χ | L12: Π | M12: Χ | N12: Π | O12: Χ | P12: Π | Q12: Χ | R12: Π | S12: Χ | T12: Π | U12: Χ | V12: Π | X12: Χ | Y12: Π | Z12: Χ | AA12: Π | AB12: Χ | AC12: Π | AD12: Χ | AE12: Π | AF12: Χ | AG12: Π | AH12: Χ | AI12: Π | AJ12: Χ | AK12: Π | AL12: Χ | AM12: Π | AN12: Χ | AO12: Π | AP12: Χ | AQ12: Π
D13: Υπόλοιπο από μεταφορά έτους 2023

Sheet ΓΑΙΑ(62)
A1: ΒΙΒΛΙΟ | X1: ΥΛΙΚΟΥ ΔΙΟΙΚΗΣΗΣ Π.Υ. ΝΟΜΟΥ ΚΕΡΚΥΡΑΣ
A3: Αύξων αριθμός δικαιολογητικών | B3: 2026 | D3: Σελίδα 62 | K3: Αερόμετρα Αεροθαλάμων | M3: Κλειδιά διάρρηξης θυρών ανελκυστήρων | O3: Νέες Σειρές εργαλείων διάρρηξης θυρών ανελκυστήρων | Q3: Γάντζοι ρυμούλκισης | S3: Δοχείο | U3: Τρίγωνα σήμανσης στάσης στάθμευσης οχημάτων | X3: Εξωλκέας ελαστικών τροχών οχημάτων | Z3: Θήκη εργαλείων οχημάτων | AB3: Καλύμματα οχημάτων πλαστικά (καμβάς) | AD3: Κιβώτια εργαλείων (πλαστικά επι οχημάτων) | AF3: Μεταλλικά κιβώτια εργαλείων "Εργαλειοθήκες" | AH3: Κλειδιά Γερμανικά εν γένει | AJ3: Σειρές Γερμανικών κλειδιών | AL3: Κλειδιά σωληνωτά για τα ημιαξόνια των τροχών οχημάτων | AN3: Ναυτικά κλειδιά | AP3: Κλειδιά Allen
D5: ΛΕΠΤΟΜΕΡΕΙΕΣ
B7: Μήνας | C7: Ημέρα
D8: Αύξων αριθμός ονομαστικού | K8: 1 | M8: 13α | O8: 13β | Q8: 20 | S8: 24 | U8: 29 | X8: 34 | Z8: 35 | AB8: 36 | AD8: 41β | AF8: 42 | AH8: 43 | AJ8: 43α | AL8: 44 | AN8: 46 | AP8: 48
D10: Γ.΄Α.΄ΙΑ.΄
D12: ΠΑΡΕΛΚΟΜΕΝΑ ΟΧΗΜΑΤΩΝ | K12: Χ | L12: Π | M12: Χ | N12: Π | O12: Χ | P12: Π | Q12: Χ | R12: Π | S12: Χ | T12: Π | U12: Χ | V12: Π | X12: Χ | Y12: Π | Z12: Χ | AA12: Π | AB12: Χ | AC12: Π | AD12: Χ | AE12: Π | AF12: Χ | AG12: Π | AH12: Χ | AI12: Π | AJ12: Χ | AK12: Π | AL12: Χ | AM12: Π | AN12: Χ | AO12: Π | AP12: Χ | AQ12: Π
B13: Ιανουάριος | C13: 1 | D13: Υπόλοιπο από μεταφορά έτους 2023 | K13: 3 | L13: 0 | M13: 16 | N13: 0 | O13: 8 | P13: 0 | Q13: 1 | R13: 0 | S13: 19 | T13: 0 | U13: 33 | V13: 0 | X13: 10 | Y13: 0 | Z13: 1 | AA13: 0 | AB13: 2 | AC13: 0 | AD13: 12 | AE13: 0 | AF13: 13 | AG13: 0 | AH13: 113 | AI13: 0 | AJ13: 21 | AK13: 0 | AL13: 1 | AM13: 0 | AN13: 4 | AO13: 0 | AP13: 20 | AQ13: 0
A14: 1 | B14: Μάιος | C14: 27 | D14: Εγγραφή με τ.α.α.20/2026 για αγορά αντ/κών από το εμπόριο (Απ.Ανάλ.Υποχρ.8409/15-05-2026)
A15: 2 | B15: Μάιος | C15: 15 | D15: Εγγραφή με τ.α.α.121 ΥΔΙΠΥΛ για Π.Σ. 5428 (Δγη 2208 Φ.544.1/15-01-2026) | U15: 1
A16: 3 | B16: Μάιος | C16: 20 | D16: Εγγραφή με τ.α.α. 985 ΥΔΙΠΥΛ για Π.Σ.5740 και Π.Σ.5741 (Δγη11526/26-06-2026) | U16: 2
A17: 4 | B17: Μάιος | C17: 22 | D17: Εγγραφή με τ.α.α.1654 ΥΔΙΠΥΛ για Π.Σ.5479 (Δγη 12424 Φ.544.1/02-03-2026) | M17: 1 | U17: 1 | AF17: 1 | AH17: 1

Sheet ΓΑΙΑ(64)
A1: ΒΙΒΛΙΟ | X1: ΥΛΙΚΟΥ ΔΙΟΙΚΗΣΗΣ Π.Υ. ΝΟΜΟΥ ΚΕΡΚΥΡΑΣ
A3: Αύξων αριθμός δικαιολογητικών | B3: 2026 | D3: Σελίδα 64 | K3: Σειρές με κλειδιά Allen | M3: Κλειδιά κύστεων οχημάτων (κλιμακοφόρου SCANIA) | O3: Κλειδιά καρυδάκια σε σειρές | Q3: Κλειδιά ειδικά αναφλεκτήρων (Μπουζόκλειδα) | S3: Κλειδιά διπλά αλυσσοπριόνων | U3: Κλειδιά ρυθμιζόμενα "Γαλλικά" εν γένει | X3: Κλειδί ρυθμιζόμενο ΠΣ 1184 | Z3: Κλειδιά πολύγωνα τύπου "Ζ" | AB3: Κλειδιά Γερμανοπο-λύγωνα | AD3: Κλειδιά Ρακόρ -Πολύγωνα - Γερμανοπολύγωνα | AF3: Κλειδιά Πολύγωνα | AH3: Κλειδιά αλλαγής τροχών διάφορα (μπουλονό-κλειδα) | AJ3: Κλειδιά τριπλής χρήσεως | AL3: Σετ Γερμανοπο-λύγωνα | AN3: Κλειδιά αναφλεκτήρων εν γένει | AP3: Κοχλιοστρόφια διάφορα (Κατσαβίδια)
D5: ΛΕΠΤΟΜΕΡΕΙΕΣ
B7: Μήνας | C7: Ημέρα
D8: Αύξων αριθμός ονομαστικού | K8: 48α | M8: 49 | O8: 50 | Q8: 52 | S8: 53 | U8: 54 | X8: 62 | Z8: 63 | AB8: 63α | AD8: 63β | AF8: 63γ | AH8: 64 | AJ8: 65 | AL8: 66α | AN8: 69 | AP8: 78
D10: Γ.΄Α.΄ΙΑ.΄
D12: ΠΑΡΕΛΚΟΜΕΝΑ ΟΧΗΜΑΤΩΝ | K12: Χ | L12: Π | M12: Χ | N12: Π | O12: Χ | P12: Π | Q12: Χ | R12: Π | S12: Χ | T12: Π | U12: Χ | V12: Π | X12: Χ | Y12: Π | Z12: Χ | AA12: Π | AB12: Χ | AC12: Π | AD12: Χ | AE12: Π | AF12: Χ | AG12: Π | AH12: Χ | AI12: Π | AJ12: Χ | AK12: Π | AL12: Χ | AM12: Π | AN12: Χ | AO12: Π | AP12: Χ | AQ12: Π
B13: Ιανουάριος | C13: 1 | D13: Υπόλοιπο από μεταφορά έτους 2023 | K13: 17 | L13: 0 | M13: 1 | N13: 0 | O13: 4 | P13: 0 | Q13: 5 | R13: 0 | S13: 2 | T13: 0 | U13: 15 | V13: 0 | X13: 1 | Y13: 0 | Z13: 31 | AA13: 0 | AB13: 13 | AC13: 0 | AD13: 1 | AE13: 0 | AF13: 2 | AG13: 0 | AH13: 39 | AI13: 0 | AJ13: 2 | AK13: 0 | AL13: 2 | AM13: 0 | AN13: 1 | AO13: 0 | AP13: 153 | AQ13: 0
A14: 1
A15: 2 | AH15: 1
A16: 3 | AH16: 2
A17: 4 | K17: 1 | U17: 1 | AH17: 1 | AP17: 6

Sheet ΓΑΙΑ(66)
A1: ΒΙΒΛΙΟ | X1: ΥΛΙΚΟΥ ΔΙΟΙΚΗΣΗΣ Π.Υ. ΝΟΜΟΥ ΚΕΡΚΥΡΑΣ
A3: Αύξων αριθμός δικαιολογητικών | B3: 2026 | D3: Σελίδα 66 | K3: Χειρομοχλός Τυλιχτήρα Υψ. Πίεσης oχήματος NISSAN | M3: Πιστόλια λίπανσης οχημάτων | O3: Πιστόλια πετρελαίου για την πλύση οχημάτων | Q3: Προβολείς οχημάτων (φορητοί) | S3: Ρυμούλκες σταθερές | U3: Ρυμούκες συρμάτινες με άγκιστρο | X3: Τρίγωνα στάσης ακινητοποίησης οχημάτων | Z3: Συρματόσχοινα ρυμούλκισης οχημάτων | AB3: Συρματόσχοινα ρυμούλκισης οχημάτων των "6"μέτρων | AD3: Συστήματα επιμήκυνσης προβολέων | AF3: Σωλήνες αναρρόφησης αφρού | AH3: Τρίποδες εν γένει προβολέων | AJ3: Τροχαλία συστήματος έλξης | AL3: Τυλικτήρες | AN3: Τύμπανα με καλώδιο "Μπαλαντέζες" | AP3: Μανιβέλλα περιέλιξης σωλήνων
D5: ΛΕΠΤΟΜΕΡΕΙΕΣ
B7: Μήνας | C7: Ημέρα
D8: Αύξων αριθμός ονομαστικού | K8: 85α | M8: 89 | O8: 90 | Q8: 91 | S8: 96 | U8: 96α | X8: 99 | Z8: 109 | AB8: 109α | AD8: 110 | AF8: 113 | AH8: 115 | AJ8: 116α | AL8: 118α | AN8: 119 | AP8: 128
D10: Γ.΄Α.΄ΙΑ.΄
D12: ΠΑΡΕΛΚΟΜΕΝΑ ΟΧΗΜΑΤΩΝ | K12: Χ | L12: Π | M12: Χ | N12: Π | O12: Χ | P12: Π | Q12: Χ | R12: Π | S12: Χ | T12: Π | U12: Χ | V12: Π | X12: Χ | Y12: Π | Z12: Χ | AA12: Π | AB12: Χ | AC12: Π | AD12: Χ | AE12: Π | AF12: Χ | AG12: Π | AH12: Χ | AI12: Π | AJ12: Χ | AK12: Π | AL12: Χ | AM12: Π | AN12: Χ | AO12: Π | AP12: Χ | AQ12: Π
B13: Ιανουάριος | C13: 1 | D13: Υπόλοιπο από μεταφορά έτους 2023 | K13: 1 | L13: 0 | M13: 1 | N13: 0 | O13: 1 | P13: 0 | Q13: 26 | R13: 0 | S13: 1 | T13: 0 | U13: 1 | V13: 0 | X13: 6 | Y13: 0 | Z13: 26 | AA13: 0 | AB13: 3 | AC13: 0 | AD13: 2 | AE13: 0 | AF13: 2 | AG13: 0 | AH13: 21 | AI13: 0 | AJ13: 1 | AK13: 0 | AL13: 3 | AM13: 0 | AN13: 32 | AO13: 0 | AP13: 2 | AQ13: 0
A14: 1
A15: 2
A16: 3
A17: 4 | Q17: 1 | AN17: 1

Sheet ΓΑΙΑ(68)
A1: ΒΙΒΛΙΟ | X1: ΥΛΙΚΟΥ ΔΙΟΙΚΗΣΗΣ Π.Υ. ΝΟΜΟΥ ΚΕΡΚΥΡΑΣ
A3: Αύξων αριθμός δικαιολογητικών | B3: 2026 | D3: Σελίδα 68 | K3: Σφυρί με λαβή ξύλινη | M3: Κλειδιά σωληνωτά σε διάφορα μεγέθη | O3: Ρυμούλκες σταθερές με άγκιστρο | Q3: Αερόκλειδα | S3: Πλαστική δεξαμενή Πετρελαίου 3.500Λίτρων | U3: Κλειδιά σωλήνων "Κάβουρες" | X3: Δεξαμενές Πλαστικές από <1> τόνο έως <5> τόνους | Z3: Δεξαμενή πτυσόμενη Αερομ/ρόμενη των 1.000 λίτρων | AB3: Έντυπο οδηγιών πτυσόμενης δεξαμενής | AD3: Εργαλείο σύσφιξης άκρης συρματόσχοινου | AF3: Σύστημα αγκύρωσης πολλαπλών σημείων | AH3: Σύστημα έλξης φορτίου με τηλεσκοπική λαβή | AJ3: Μεταλλικό δοχείο καυσίμων | AL3: Δοχεία Καυσίμων | AN3: Σειρές εργαλείων ανοίγματος θυρών οχημάτων | AP3: Κλειδια "ΤΑΦ" (καρυδακι) Νο 10
D5: ΛΕΠΤΟΜΕΡΕΙΕΣ
B7: Μήνας | C7: Ημέρα
D8: Αύξων αριθμός ονομαστικού | K8: 136 | M8: 137 | O8: 142α | Q8: 186 | S8: 197 | U8: 201 | X8: 203 | Z8: 205 | AB8: 205δ | AD8: 207 | AF8: 208 | AH8: 209 | AJ8: 210 | AL8: 210α | AN8: 214 | AP8: 221
D10: Γ.΄Α.΄ΙΑ.΄
D12: ΠΑΡΕΛΚΟΜΕΝΑ ΟΧΗΜΑΤΩΝ | K12: Χ | L12: Π | M12: Χ | N12: Π | O12: Χ | P12: Π | Q12: Χ | R12: Π | S12: Χ | T12: Π | U12: Χ | V12: Π | X12: Χ | Y12: Π | Z12: Χ | AA12: Π | AB12: Χ | AC12: Π | AD12: Χ | AE12: Π | AF12: Χ | AG12: Π | AH12: Χ | AI12: Π | AJ12: Χ | AK12: Π | AL12: Χ | AM12: Π | AN12: Χ | AO12: Π | AP12: Χ | AQ12: Π
B13: Ιανουάριος | C13: 1 | D13: Υπόλοιπο από μεταφορά έτους 2023 | K13: 60 | L13: 0 | M13: 6 | N13: 0 | O13: 1 | P13: 0 | Q13: 2 | R13: 0 | S13: 1 | T13: 0 | U13: 12 | V13: 0 | X13: 2 | Y13: 0 | Z13: 1 | AA13: 0 | AB13: 1 | AC13: 0 | AD13: 1 | AE13: 0 | AF13: 1 | AG13: 0 | AH13: 1 | AI13: 0 | AJ13: 3 | AK13: 0 | AL13: 4 | AM13: 0 | AN13: 1 | AO13: 0 | AP13: 1 | AQ13: 0
A14: 1
A15: 2
A16: 3
A17: 4 | K17: 2

Sheet ΓΑΙΑ(70)
A1: ΒΙΒΛΙΟ | X1: ΥΛΙΚΟΥ ΔΙΟΙΚΗΣΗΣ Π.Υ. ΝΟΜΟΥ ΚΕΡΚΥΡΑΣ
A3: Αύξων αριθμός δικαιολογητικών | B3: 2026 | D3: Σελίδα 70 | K3: Κλειδια "ΤΑΦ" (καρυδακι) Νο 13 | M3: Δίχτυ δεξαμενής | O3: Ιμάντας πρόσδεσης δεξαμενής | Q3: Κλειδια "ΤΑΦ" Διάφορα (καρυδάκι) Νο 6, 7, 8, ..κλπ | S3: Αισθητήρες στάθμης νερού δεξαμενής MAXBOTIX υδροφόρων οχημάτων | U3: Μηχανισμοί Εκτόξευσης Νερού Υαλοκαθαριστήρων | X3: Δεξαμενές καυσίμου οχημάτων | Z3: Καθρέπτες Οχημάτων | AB3: Κλειδιά Οχημάτων Immobilizer | AD3: Μαρκούτσια Διάφορα | AF3: Δεξαμενές Καυσίμων | AH3: Βραχίονες Υαλοκαθαριστήρων | AJ3: Ηλεκτρικά | AL3: Δεξαμενές Ύδατος Φορητές | AN3: Ανταλλακτικά Φίτρου Βενζίνης | AP3: Κάμερα Οχημάτων
D5: ΛΕΠΤΟΜΕΡΕΙΕΣ
B7: Μήνας | C7: Ημέρα
D8: Αύξων αριθμός ονομαστικού | K8: 222 | M8: 224 | O8: 225 | Q8: 228 | S8: 230 | U8: 178 | X8: 21 | Z8: 39α | AB8: 234 | AD8: 83 | AF8: 21γ | AH8: 17 | AJ8: 164 | AL8: 229 | AN8: 12 | AP8: 238
D10: Γ.΄Α.΄ΙΑ.΄
